Workbook

Sheet Summary
B1: Folio3 Project Estimation
B2: Parts Quick Order
B3: Summary of Estimates
B5: Client Name | C5: Demo Garage
B6: Project Manager | C6: mhamza
B7: Date | C7: 2026-10-05
B8: Version | C8: 1
C9: Efforts (in hours)
B10: Task Summary | C10: Minimum | D10: Maximum | E10: Comments | H10: Avg | I10: Resources | J10: Weeks
B11: Backend Development Estimates | C11: ='Dev Backend Estimates'!D6 -> 62.58 | D11: ='Dev Backend Estimates'!E6 -> 110.56 | E11: Grand total of the Backend sheet | H11: =ROUND((C11+D11)/2,2) -> 86.57 | I11: 1 | J11: =ROUND(H11/($C$48*I11),2) -> 2.16
B12: Mobile Development Estimates | C12: ='Dev Mobile Estimates'!D6 -> 0 | D12: ='Dev Mobile Estimates'!E6 -> 0 | E12: Grand total of the Mobile sheet | H12: =ROUND((C12+D12)/2,2) -> 0 | I12: 1 | J12: =ROUND(H12/($C$48*I12),2) -> 0
B13: Admin Development Estimates | C13: ='Dev Web Estimates'!D6 -> 64.41 | D13: ='Dev Web Estimates'!E6 -> 107.6 | E13: Grand total of the Web / Admin sheet | H13: =ROUND((C13+D13)/2,2) -> 86.01 | I13: 1 | J13: =ROUND(H13/($C$48*I13),2) -> 2.15
B14: QA Estimates | C14: ='QA Estimates'!D6 -> 22.9 | D14: ='QA Estimates'!E6 -> 43.8 | E14: Grand total of the QA sheet | H14: =ROUND((C14+D14)/2,2) -> 33.35 | I14: 1 | J14: =ROUND(H14/($C$48*I14),2) -> 0.83
B15: GD Estimates | C15: ='Other Estimates'!D10 -> 0 | D15: ='Other Estimates'!E10 -> 0 | E15: Other Estimates sheet | H15: =ROUND((C15+D15)/2,2) -> 0 | I15: 1 | J15: =ROUND(H15/($C$48*I15),2) -> 0
B16: PM Estimates | C16: ='Other Estimates'!D16 -> 4 | D16: ='Other Estimates'!E16 -> 8 | E16: Other Estimates sheet | H16: =ROUND((C16+D16)/2,2) -> 6 | I16: 1 | J16: =ROUND(H16/($C$48*I16),2) -> 0.15
B17: PDM Estimates | C17: ='Other Estimates'!D22 -> 2.88 | D17: ='Other Estimates'!E22 -> 5.76 | E17: Other Estimates sheet | H17: =ROUND((C17+D17)/2,2) -> 4.32 | I17: 1 | J17: =ROUND(H17/($C$48*I17),2) -> 0.11
B18: Cross-cutting Estimates | C18: ='Other Estimates'!D28 -> 0 | D18: ='Other Estimates'!E28 -> 0 | E18: Other Estimates sheet: deployment, documentation and the like | H18: =ROUND((C18+D18)/2,2) -> 0 | I18: 1 | J18: =ROUND(H18/($C$48*I18),2) -> 0
B19: Design Estimates | C19: ='Design Estimates'!D6 -> 2 | D19: ='Design Estimates'!E6 -> 4 | E19: Counted in the total only when Design is switched on below | H19: =ROUND((C19+D19)/2,2) -> 3 | I19: 1 | J19: =ROUND(H19/($C$48*I19),2) -> 0.08
B20: Total | C20: =SUM(C11:C18)+IF($C$47="Yes",C19,0) -> 158.77 | D20: =SUM(D11:D18)+IF($C$47="Yes",D19,0) -> 279.72 | H20: =ROUND((C20+D20)/2,2) -> 219.25
B23: List of Special Considerations, where applicable:
B24: Tasks | C24: Action | E24: Comments
B25: Application type (mobile, desktop, web) | C25: Backend + Web | E25: From the tracks that have work
B26: Platforms/OS supported | C26: Not specified | E26: Confirm with the client
B27: Browsers supported | C27: Assumed: The latest two versions of Chrome, Edge, Safari and Firefox. | E27: Factory assumption ASM-17, confirm with the client
B28: Deployment (cloud, dedicated server, enterprise internal network) | C28: Not specified | E28: Confirm with the client
B29: Performance, Load requirements | C29: Assumed: Up to 1,000 users and 100,000 records in the first year. | E29: Factory assumption ASM-16, confirm with the client
B30: Security requirements | C30: Not specified | E30: Confirm with the client
B31: Documentation requirements | C31: Not specified | E31: Confirm with the client
B32: Other custom? | C32: No
B46: Parameters
B47: Include Design in total | C47: Yes
B48: Hours per week | C48: 40
B49: Feedback rounds | C49: 2
B50: Stack chosen by | C50: client
B51: Delivery model | C51: Solely agentic
B55: How to read the hours
B56: Each task's Minimum and Maximum are the hours it takes to deliver. Most of the work is done by AI agents; a person's hours are added only where a person is needed (client acceptance, design sign-off, project liaison, accounts and keys).
B58: Elapsed time
B59: Planning (minutes) | C59: 0
B60: Build critical path (days) | C60: 10.45 | D60: 17.74
...

Sheet Dev Backend Estimates
B2: Development Estimates for Parts Quick Order
B3: 2026-10-05
B4: by mhamza
C6: Grand Total (in hours) | D6: =D26+D31+D36 -> 62.58 | E6: =E26+E31+E36 -> 110.56 | F6: Sum of development, other activities and research efforts.
B8: S.No | C8: Task | D8: Minimum | E8: Maximum | F8: Comments | G8: Executor | H8: Requirement id(s) | I8: Task id
B9: 1 | C9: Portal shell, navigation and cross-cutting | D9: =SUM(D10:D10) -> 17.47 | E9: =SUM(E10:E10) -> 30.58
C10: Environments, CI/CD and hosting for API and portal | D10: 17.47 | E10: 30.58 | F10: Environment setup delivers no requirement on its own | G10: Joint | I10: EST-1
B12: 2 | C12: Find parts | D12: =SUM(D13:D14) -> 5.52 | E12: =SUM(E13:E14) -> 11.04
C13: GET /api/parts: search, filters, paging, stock state | D13: 3.9 | E13: 7.8 | F13: Sorted by name A–Z, 20 per page, total count; Fields image (or null), name, partNumber, brand, price in GBP with 2 decimals, stockState, stock (whole number); Stock state: In stock (≥5), Low stock (n left) (1–4), Out of stock (0); Search q of at least 2 characters, case-insensitive, on name or part number; 1 character applies no filter; One category and one brand filter combined with search; All means no filter; Empty result returns 200 with empty list and total 0; p95 under 500 ms with 5,000 parts | G13: Factory | H13: REQ-2, REQ-3, REQ-4, REQ-5, REQ-38 | I13: EST-4
C14: GET /api/parts/brands | D14: 1.62 | E14: 3.24 | F14: Distinct brand list taken from the parts data | G14: Factory | H14: REQ-5 | I14: EST-5
B16: 3 | C16: Placing orders (orders API) | D16: =SUM(D17:D18) -> 14.96 | E16: =SUM(E17:E18) -> 26.72
C17: Orders data model, migrations and seed data | D17: 2.16 | E17: 4.32 | F17: orders table: buyer ID, order number, date placed, delivery address, delivery option (STANDARD/NEXT_DAY), total, status; order_lines table: order, part number (refers to existing parts), quantity, unit price; Status values Placed, Packed, Dispatched, Delivered, Cancelled; Database sequence for ORD- + 6 zero-padded digits (ORD-000001); Indexes on buyer and date placed for 100,000 order records (NFR-2); Parts table stays read-only; Seed of 5,000 parts for the load test | G17: Factory | H17: REQ-20, REQ-28, REQ-30, REQ-38 | I17: EST-2
C18: POST /api/orders: place order rules | D18: 12.8 | E18: 22.4 | F18: Validation 400 with error field: no lines, quantity outside 1–99, unknown part number, address outside 5–200 characters, missing or unknown delivery option; Stock re-check: 409 listing each affected part number with available stock, no order saved; Unit price from current part price; client-sent price ignored; Total = subtotal + delivery charge (Standard £0.00, Next day £9.99); Status Placed and sequential order number ORD-000001; 201 response with orderNumber, status and total; Stock quantity in parts database left unchanged | G18: Factory | H18: REQ-20, REQ-21, REQ-22, REQ-25 | I18: EST-6
B20: 4 | C20: My orders | D20: =SUM(D21:D24) -> 24.63 | E20: =SUM(E21:E24) -> 42.22
C21: Buyer identity from existing company login session | D21: 13.1 | E21: 20.97 | F21: Validate existing company login session token or cookie on every API request (ASM-5); Read buyer ID from session for order ownership; Expose signed-in buyer ID to the portal for the cart storage key | G21: Joint | H21: REQ-27, REQ-16 | I21: EST-3
C22: GET /api/orders: buyer's orders list with status filter | D22: 2.7 | E22: 5.4 | F22: Only the signed-in buyer's orders; Newest first; Fields order number, datePlaced, itemCount (total of quantities), total, status; status query filter; Empty list with 200 when no orders | G22: Factory | H22: REQ-27, REQ-28, REQ-29, REQ-35 | I22: EST-7
C23: GET /api/orders/{orderNumber}: order detail | D23: 1.62 | E23: 3.24 | F23: Lines with part number, name, quantity, unit price; Delivery address, delivery option, total, status; 404 for another buyer's order | G23: Factory | H23: REQ-27, REQ-30 | I23: EST-8
C24: POST /api/orders/{orderNumber}/cancel: cancel rules | D24: 7.21 | E24: 12.61 | F24: Cancel only if status is still Placed: set Cancelled, return 200 with status Cancelled; 409 with error message when no longer Placed, status unchanged; 404 for another buyer's order, status unchanged; Stock unchanged on cancel | G24: Factory | H24: REQ-33, REQ-34, REQ-27, REQ-25 | I24: EST-9
C26: Development Total Efforts (in hours) | D26: =D9+D12+D16+D20 -> 62.58 | E26: =E9+E12+E16+E20 -> 110.56
B29: S.No | C29: Other Development Activities | D29: Minimum | E29: Maximum | F29: Comments | G29: Executor | H29: Requirement id(s) | I29: Task id
B30: 1 | C30: None | D30: 0 | E30: 0
C31: Post Development Activities Total Efforts (in hours) | D31: =SUM(D30:D30) -> 0 | E31: =SUM(E30:E30) -> 0
B34: S.No | C34: Research Task (if any) | D34: Minimum | E34: Maximum | F34: Comments | G34: Executor | H34: Requirement id(s) | I34: Task id
B35: 1 | C35: None | D35: 0 | E35: 0 | F35: No research task in this estimate
C36: Research Total Efforts (in hours) | D36: =SUM(D35:D35) -> 0 | E36: =SUM(E35:E35) -> 0
B39: S.No | C39: Assumptions & Constraints
B40: 1 | C40: Does the 'Place order' button also need the cart to have at least one line, or is that already covered because checkout is hidden when the cart is empty? → assumed: Covered already: checkout is hidden when the cart is empty, and the API also refuses an order with no lines
B41: 2 | C41: Does placing (or cancelling) an order change the stock quantity in the existing parts database? → assumed: No: stock is read-only and orders never change it
B42: 3 | C42: What happens when a cart quantity is more than the current stock (or the part is now out of stock) at the moment the buyer presses 'Place order'? → assumed: The API checks stock again, rejects the order, lowers the affected lines to the stock now available with 'Only n available', and keeps the cart
B43: 4 | C43: Where is the cart kept? → assumed: In the browser's local storage for the signed-in buyer (kept across page reloads on the same device)
B44: 5 | C44: How does the API find out which buyer is making a request through the existing company login? → assumed: The API checks the existing company login's session token or cookie and reads the buyer ID from it
B45: 6 | C45: Nothing in this work moves an order to Packed, Dispatched or Delivered (no admin screens, no integrations). How do statuses change after Placed? → assumed: Staff update the status directly in the database, outside this work; the portal only shows it
B46: 7 | C46: Which unit price is saved on an order line, and what does the order 'total' include? → assumed: The part's current price when the order is placed; total = subtotal + delivery charge
B47: 8 | C47: How are 'ORD-' + 6-digit order numbers generated? → assumed: Sequential from a database sequence, zero-padded (ORD-000001)
B48: 9 | C48: Should the delivery prices (£0 / £9.99), the stock thresholds (5) and the page size (20) be fixed in the code or set in configuration? → assumed: Fixed constants in the code
B49: 10 | C49: What happens if the order's status changes from Placed (e.g. to Packed) after the buyer opened it but before they confirm cancelling? → assumed: The API cancels only if the status is still Placed; otherwise it refuses, shows a message and refreshes the order
B50: 11 | C50: What happens if placing an order fails (network or server error)? → assumed: Show an error message, keep the cart and checkout details, and let the buyer try again
B51: 12 | C51: What happens when a quantity is set to 0, left blank, set above 99, or isn't a whole number? → assumed: Set it to the nearest value in range (blank or 0 becomes 1, above 99 becomes 99)
... B67: 28 | C67: Split before the build: EST-1, EST-3, EST-6, EST-13 (agent work over 16 h or very large is split into smaller tasks; the hours stay as estimated).
B70: S.No | C70: Risks
...

Sheet Dev Mobile Estimates
B2: Development Estimates for Parts Quick Order
B3: 2026-10-05
B4: by mhamza
B5: Not in scope: no work in this estimate
C6: Grand Total (in hours) | D6: =D11+D16+D21 -> 0 | E6: =E11+E16+E21 -> 0 | F6: Sum of development, other activities and research efforts.
B8: S.No | C8: Task | D8: Minimum | E8: Maximum | F8: Comments | G8: Executor | H8: Requirement id(s) | I8: Task id
C9: None | D9: 0 | E9: 0
C11: Development Total Efforts (in hours) | D11: =D9 -> 0 | E11: =E9 -> 0
B14: S.No | C14: Other Development Activities | D14: Minimum | E14: Maximum | F14: Comments | G14: Executor | H14: Requirement id(s) | I14: Task id
B15: 1 | C15: None | D15: 0 | E15: 0
C16: Post Development Activities Total Efforts (in hours) | D16: =SUM(D15:D15) -> 0 | E16: =SUM(E15:E15) -> 0
B19: S.No | C19: Research Task (if any) | D19: Minimum | E19: Maximum | F19: Comments | G19: Executor | H19: Requirement id(s) | I19: Task id
B20: 1 | C20: None | D20: 0 | E20: 0 | F20: No research task in this estimate
C21: Research Total Efforts (in hours) | D21: =SUM(D20:D20) -> 0 | E21: =SUM(E20:E20) -> 0

Sheet Dev Web Estimates
B2: Development Estimates for Parts Quick Order
B3: 2026-10-05
B4: by mhamza
C6: Grand Total (in hours) | D6: =D25+D30+D35 -> 64.41 | E6: =E25+E30+E35 -> 107.6 | F6: Sum of development, other activities and research efforts.
B8: S.No | C8: Task | D8: Minimum | E8: Maximum | F8: Comments | G8: Executor | H8: Requirement id(s) | I8: Task id
B9: 1 | C9: Portal shell, navigation and cross-cutting | D9: =SUM(D10:D11) -> 11.35 | E9: =SUM(E10:E11) -> 21.5
C10: Portal app shell (web) | D10: 4.8 | E10: 8.4 | F10: Routes /parts, /cart, /orders; Header with links to the other two screens and live cart count; Company login session wiring and buyer ID; Error page; Responsive layout without horizontal scroll from 360 px; Visible focus and keyboard navigation; Prices formatted as £ with 2 decimals, English only (NFR-6) | G10: Factory | H10: REQ-1, REQ-9, REQ-36, REQ-37 | I10: EST-10
C11: Production release of API and portal | D11: 6.55 | E11: 13.1 | F11: Production launch delivers no requirement on its own | G11: Joint | I11: EST-22
B13: 2 | C13: Find parts | D13: =SUM(D14:D14) -> 6 | E13: =SUM(E14:E14) -> 10
C14: Find parts screen (web) | D14: 6 | E14: 10 | F14: Search box with "Type at least 2 characters" hint; Category and brand filters with All; Result rows: image, name, part number, brand, price, stock badge with text; Previous/Next paging, back to page 1 on search or filter change; Add to cart, disabled when out of stock; header count bumps with success message; Go to cart (n) link; States: loading skeleton, empty "No parts match" with Clear search and filters, error with Try again, out of stock, low stock, added; First page displayed within 2 seconds with 5,000 parts | G14: Factory | H14: REQ-1, REQ-2, REQ-3, REQ-4, REQ-5, REQ-6, REQ-7, REQ-8, REQ-9, REQ-10, REQ-36, REQ-37, REQ-38 | I14: EST-12
B16: 3 | C16: Cart and checkout | D16: =SUM(D17:D19) -> 31.66 | E16: =SUM(E17:E19) -> 50.9
C17: CartStore in browser local storage per buyer | D17: 7.02 | E17: 11.7 | F17: addPart: add line quantity 1 or +1; out-of-stock part not added; capped at stock with "Only n available"; count(): total of all quantities; lines(): name, partNumber, unitPrice, quantity, lineTotal; setQuantity: blank/0 → 1, above 99 → 99, non-whole → nearest; above stock → stock with "Only n available"; removeLine; subtotal() and totals(STANDARD £0.00 / NEXT_DAY £9.99); Persist lines in local storage under buyer ID; refresh(partsClient): current prices only, remove 0-stock lines with "<part name> is now out of stock", on failure error field and null prices/totals; applyStockLimits from 409: lower lines with "Only n available", remove 0-stock lines with message, keep others | G17: Factory | H17: REQ-8, REQ-9, REQ-10, REQ-11, REQ-12, REQ-13, REQ-14, REQ-15, REQ-16, REQ-19, REQ-39, REQ-41, REQ-42, REQ-43 | I17: EST-11
C18: Cart lines with live prices (web) | D18: 19.6 | E18: 30.8 | F18: Lines table: part, part no., unit price, editable qty, line total, Remove; Instant recalculation of line and order totals; Quantity correction with "Only n available"; Inline alert "<part name> is now out of stock" when a line is removed; Loading state while current prices are fetched; Price error state: lines without prices, error message, Try again, checkout hidden; Empty state "Your cart is empty" with link to Find parts, checkout hidden | G18: Factory | H18: REQ-9, REQ-11, REQ-12, REQ-13, REQ-14, REQ-15, REQ-17, REQ-41, REQ-42, REQ-43, REQ-36, REQ-37 | I18: EST-13
C19: Checkout form and place order (web) | D19: 5.04 | E19: 8.4 | F19: Delivery address textarea 5–200 characters, empty each time, with labelled error; Delivery option radio Standard £0.00 / Next day £9.99; Order summary: items, subtotal, delivery charge, total; Place order enabled only when valid; disabled while submitting (one request); Success: show order number, empty cart, link to My orders; Network error toast: check My orders before retrying; server error toast: cart and details kept; 409 conflict: apply stock limits to lines with messages | G19: Factory | H19: REQ-18, REQ-19, REQ-20, REQ-21, REQ-22, REQ-23, REQ-24, REQ-39, REQ-40, REQ-36, REQ-37 | I19: EST-14
B21: 4 | C21: My orders | D21: =SUM(D22:D23) -> 15.4 | E21: =SUM(E22:E23) -> 25.2
C22: My orders list (web) | D22: 8.4 | E22: 14 | F22: Table: order, date placed, items, total, status (text label), newest first; Status filter chips: All statuses, Placed, Packed, Dispatched, Delivered, Cancelled; View order opens panel on the same page; States: loading skeleton, empty "No orders yet" with link to Find parts, filtered empty, error with Try again | G22: Factory | H22: REQ-1, REQ-28, REQ-29, REQ-35, REQ-36, REQ-37 | I22: EST-15
C23: Order detail drawer, timeline and cancel (web) | D23: 7 | E23: 11.2 | F23: Drawer overlay: lines, address, delivery option, total, status; Timeline Placed → Packed → Dispatched → Delivered with current status marked by text; Cancel order button only while Placed; Confirm dialog (Yes, cancel order / Keep order); Success toast and status Cancelled; 409 toast: can no longer be cancelled, panel refreshes | G23: Factory | H23: REQ-1, REQ-30, REQ-31, REQ-32, REQ-33, REQ-34, REQ-37 | I23: EST-16
C25: Development Total Efforts (in hours) | D25: =D9+D13+D16+D21 -> 64.41 | E25: =E9+E13+E16+E21 -> 107.6
B28: S.No | C28: Other Development Activities | D28: Minimum | E28: Maximum | F28: Comments | G28: Executor | H28: Requirement id(s) | I28: Task id
B29: 1 | C29: None | D29: 0 | E29: 0
C30: Post Development Activities Total Efforts (in hours) | D30: =SUM(D29:D29) -> 0 | E30: =SUM(E29:E29) -> 0
B33: S.No | C33: Research Task (if any) | D33: Minimum | E33: Maximum | F33: Comments | G33: Executor | H33: Requirement id(s) | I33: Task id
B34: 1 | C34: None | D34: 0 | E34: 0 | F34: No research task in this estimate
C35: Research Total Efforts (in hours) | D35: =SUM(D34:D34) -> 0 | E35: =SUM(E34:E34) -> 0
B38: S.No | C38: Assumptions & Constraints
B39: 1 | C39: Does the 'Place order' button also need the cart to have at least one line, or is that already covered because checkout is hidden when the cart is empty? → assumed: Covered already: checkout is hidden when the cart is empty, and the API also refuses an order with no lines
B40: 2 | C40: Does placing (or cancelling) an order change the stock quantity in the existing parts database? → assumed: No: stock is read-only and orders never change it
B41: 3 | C41: What happens when a cart quantity is more than the current stock (or the part is now out of stock) at the moment the buyer presses 'Place order'? → assumed: The API checks stock again, rejects the order, lowers the affected lines to the stock now available with 'Only n available', and keeps the cart
B42: 4 | C42: Where is the cart kept? → assumed: In the browser's local storage for the signed-in buyer (kept across page reloads on the same device)
B43: 5 | C43: How does the API find out which buyer is making a request through the existing company login? → assumed: The API checks the existing company login's session token or cookie and reads the buyer ID from it
B44: 6 | C44: Nothing in this work moves an order to Packed, Dispatched or Delivered (no admin screens, no integrations). How do statuses change after Placed? → assumed: Staff update the status directly in the database, outside this work; the portal only shows it
B45: 7 | C45: Which unit price is saved on an order line, and what does the order 'total' include? → assumed: The part's current price when the order is placed; total = subtotal + delivery charge
B46: 8 | C46: How are 'ORD-' + 6-digit order numbers generated? → assumed: Sequential from a database sequence, zero-padded (ORD-000001)
B47: 9 | C47: Should the delivery prices (£0 / £9.99), the stock thresholds (5) and the page size (20) be fixed in the code or set in configuration? → assumed: Fixed constants in the code
B48: 10 | C48: What happens if the order's status changes from Placed (e.g. to Packed) after the buyer opened it but before they confirm cancelling? → assumed: The API cancels only if the status is still Placed; otherwise it refuses, shows a message and refreshes the order
B49: 11 | C49: What happens if placing an order fails (network or server error)? → assumed: Show an error message, keep the cart and checkout details, and let the buyer try again
B50: 12 | C50: What happens when a quantity is set to 0, left blank, set above 99, or isn't a whole number? → assumed: Set it to the nearest value in range (blank or 0 becomes 1, above 99 becomes 99)
... B66: 28 | C66: Split before the build: EST-1, EST-3, EST-6, EST-13 (agent work over 16 h or very large is split into smaller tasks; the hours stay as estimated).
B69: S.No | C69: Risks
B70: 1 | C70: Estimates will increase in case of change in requirement

Sheet QA Estimates
B2: QA Estimates for Parts Quick Order
B3: 2026-10-05
B4: by mhamza
C6: Grand Total Efforts (in hours) | D6: =D23 -> 22.9 | E6: =E23 -> 43.8 | F6: Sum of QA and Misc.
B8: S.No | C8: Estimation Summary | D8: Minimum | E8: Maximum | F8: Comments | G8: Executor | H8: Requirement id(s) | I8: Task id
B9: 1 | C9: Test Plan/Strategy | D9: 0 | E9: 0 | F9: Test planning, with the test plan, strategy and traceability matrix as outputs. Not sized in this estimate
B10: 2 | C10: Set up of Test Environments | D10: 0 | E10: 0 | F10: Setting up code and white box test environments. Not sized in this estimate
B11: 3 | C11: Validation and Smoke test cases | D11: =SUM(D12:D14) -> 9 | E11: =SUM(E12:E14) -> 18 | F11: Test cases to execute while debugging and white box testing
C12: Test cases: Find parts and parts API, including load test | D12: 3 | E12: 6 | F12: API cases AC-2.x to AC-7.x; Load test AC-38.1 (p95 < 500 ms) and AC-38.2 (2 s first page); Manual cases for paging reset, clear button, disabled Add to cart | G12: Factory | H12: REQ-2, REQ-3, REQ-4, REQ-5, REQ-6, REQ-7, REQ-8, REQ-10, REQ-38 | I12: EST-17
C13: Test cases: Cart, checkout and place order | D13: 3 | E13: 6 | F13: CartStore and CheckoutForm unit cases; Orders API cases for 201, 400, 409, stock unchanged; Manual cases for error, conflict, price failure and success states | G13: Factory | H13: REQ-11, REQ-12, REQ-13, REQ-14, REQ-15, REQ-16, REQ-17, REQ-18, REQ-19, REQ-20, REQ-21, REQ-22, REQ-23, REQ-24, REQ-25, REQ-39, REQ-40, REQ-41, REQ-42, REQ-43 | I13: EST-18
C14: Test cases: My orders and cancel | D14: 3 | E14: 6 | F14: Ownership 404 cases; List order, filter, detail cases; Cancel success and 409 cases, confirmation decline | G14: Factory | H14: REQ-27, REQ-28, REQ-29, REQ-30, REQ-31, REQ-32, REQ-33, REQ-34, REQ-35 | I14: EST-19
B15: 4 | C15: Validation testing | D15: =SUM(D16:D16) -> 6 | E15: =SUM(E16:E16) -> 10 | F15: Testing cycles; the detail is below
C16: Testing Cycle 1 | D16: =D29 -> 6 | E16: =E29 -> 10
B17: 5 | C17: Smoke testing | D17: 0 | E17: 0 | F17: Smoke testing after each deployment, including preparation. Not sized in this estimate
B18: 6 | C18: Multi Browser Compatibility testing | D18: =SUM(D19:D19) -> 3.9 | E18: =SUM(E19:E19) -> 7.8 | F18: Browser, OS and device compatibility
C19: Test cases: accessibility, responsive and browsers | D19: 3.9 | E19: 7.8 | F19: Automated axe scan per screen, 0 serious or critical (NFR-3); Keyboard-only journey with screen reader labels; 360/768/1280 px widths on latest 2 Chrome, Edge, Safari, Firefox | G19: Factory | H19: REQ-1, REQ-36, REQ-37 | I19: EST-20
B20: 7 | C20: UAT | D20: =SUM(D21:D21) -> 4 | E20: =SUM(E21:E21) -> 8 | F20: Client user acceptance testing support
C21: Client acceptance testing | D21: 4 | E21: 8 | F21: Client UAT delivers no requirement on its own | G21: Human | I21: EST-24
B22: 8 | C22: Misc. Optional testing | D22: 0 | E22: 0 | F22: Other testing named in the breakdown, and supervisor gate time. Not sized in this estimate
C23: Total QA Efforts | D23: =D9+D10+D11+D15+D17+D18+D20+D22 -> 22.9 | E23: =E9+E10+E11+E15+E17+E18+E20+E22 -> 43.8 | F23: Total hours of QA
B26: S.No | C26: Validation Testing | D26: Minimum | E26: Maximum | F26: Comments | G26: Executor | H26: Requirement id(s) | I26: Task id
C27: Testing Cycle 1
B28: 1 | C28: End-to-end test: find, add, check out, view and cancel | D28: 6 | E28: 10 | F28: Search, add to cart, header count, place order, order number, open in My orders, cancel | G28: Factory | H28: REQ-1, REQ-4, REQ-8, REQ-9, REQ-18, REQ-20, REQ-23, REQ-28, REQ-30, REQ-32, REQ-33 | I28: EST-21
C29: Total Testing Cycle 1 | D29: =D28 -> 6 | E29: =E28 -> 10 | F29: Sum of testing cycle 1
B32: S.No | C32: Assumptions & Constraints
B33: 1 | C33: Does the 'Place order' button also need the cart to have at least one line, or is that already covered because checkout is hidden when the cart is empty? → assumed: Covered already: checkout is hidden when the cart is empty, and the API also refuses an order with no lines
B34: 2 | C34: Does placing (or cancelling) an order change the stock quantity in the existing parts database? → assumed: No: stock is read-only and orders never change it
B35: 3 | C35: What happens when a cart quantity is more than the current stock (or the part is now out of stock) at the moment the buyer presses 'Place order'? → assumed: The API checks stock again, rejects the order, lowers the affected lines to the stock now available with 'Only n available', and keeps the cart
B36: 4 | C36: Where is the cart kept? → assumed: In the browser's local storage for the signed-in buyer (kept across page reloads on the same device)
B37: 5 | C37: How does the API find out which buyer is making a request through the existing company login? → assumed: The API checks the existing company login's session token or cookie and reads the buyer ID from it
B38: 6 | C38: Nothing in this work moves an order to Packed, Dispatched or Delivered (no admin screens, no integrations). How do statuses change after Placed? → assumed: Staff update the status directly in the database, outside this work; the portal only shows it
B39: 7 | C39: Which unit price is saved on an order line, and what does the order 'total' include? → assumed: The part's current price when the order is placed; total = subtotal + delivery charge
B40: 8 | C40: How are 'ORD-' + 6-digit order numbers generated? → assumed: Sequential from a database sequence, zero-padded (ORD-000001)
B41: 9 | C41: Should the delivery prices (£0 / £9.99), the stock thresholds (5) and the page size (20) be fixed in the code or set in configuration? → assumed: Fixed constants in the code
B42: 10 | C42: What happens if the order's status changes from Placed (e.g. to Packed) after the buyer opened it but before they confirm cancelling? → assumed: The API cancels only if the status is still Placed; otherwise it refuses, shows a message and refreshes the order
B43: 11 | C43: What happens if placing an order fails (network or server error)? → assumed: Show an error message, keep the cart and checkout details, and let the buyer try again
B44: 12 | C44: What happens when a quantity is set to 0, left blank, set above 99, or isn't a whole number? → assumed: Set it to the nearest value in range (blank or 0 becomes 1, above 99 becomes 99)
... B60: 28 | C60: Split before the build: EST-1, EST-3, EST-6, EST-13 (agent work over 16 h or very large is split into smaller tasks; the hours stay as estimated).
B63: S.No | C63: Risks
B64: 1 | C64: Estimates will increase in case of change in requirement

Sheet Design Estimates
B2: Design Estimates for Parts Quick Order
B3: 2026-10-05
B4: by mhamza
C6: Grand Total (in hours) | D6: =D12+D17+D22 -> 2 | E6: =E12+E17+E22 -> 4 | F6: Sum of development, other activities and research efforts.
B8: S.No | C8: Task | D8: Minimum | E8: Maximum | F8: Comments | G8: Executor | H8: Requirement id(s) | I8: Task id
B9: 1 | C9: Portal shell, navigation and cross-cutting | D9: =SUM(D10:D10) -> 2 | E9: =SUM(E10:E10) -> 4
C10: Client design review and approval | D10: 2 | E10: 4 | F10: Client walkthrough and sign-off of the approved design | G10: Human | I10: EST-23
C12: Development Total Efforts (in hours) | D12: =D9 -> 2 | E12: =E9 -> 4
B15: S.No | C15: Other Development Activities | D15: Minimum | E15: Maximum | F15: Comments | G15: Executor | H15: Requirement id(s) | I15: Task id
B16: 1 | C16: None | D16: 0 | E16: 0
C17: Post Development Activities Total Efforts (in hours) | D17: =SUM(D16:D16) -> 0 | E17: =SUM(E16:E16) -> 0
B20: S.No | C20: Research Task (if any) | D20: Minimum | E20: Maximum | F20: Comments | G20: Executor | H20: Requirement id(s) | I20: Task id
B21: 1 | C21: None | D21: 0 | E21: 0 | F21: No research task in this estimate
C22: Research Total Efforts (in hours) | D22: =SUM(D21:D21) -> 0 | E22: =SUM(E21:E21) -> 0
B25: S.No | C25: Assumptions & Constraints
B26: 1 | C26: Does the 'Place order' button also need the cart to have at least one line, or is that already covered because checkout is hidden when the cart is empty? → assumed: Covered already: checkout is hidden when the cart is empty, and the API also refuses an order with no lines
B27: 2 | C27: Does placing (or cancelling) an order change the stock quantity in the existing parts database? → assumed: No: stock is read-only and orders never change it
B28: 3 | C28: What happens when a cart quantity is more than the current stock (or the part is now out of stock) at the moment the buyer presses 'Place order'? → assumed: The API checks stock again, rejects the order, lowers the affected lines to the stock now available with 'Only n available', and keeps the cart
B29: 4 | C29: Where is the cart kept? → assumed: In the browser's local storage for the signed-in buyer (kept across page reloads on the same device)
B30: 5 | C30: How does the API find out which buyer is making a request through the existing company login? → assumed: The API checks the existing company login's session token or cookie and reads the buyer ID from it
B31: 6 | C31: Nothing in this work moves an order to Packed, Dispatched or Delivered (no admin screens, no integrations). How do statuses change after Placed? → assumed: Staff update the status directly in the database, outside this work; the portal only shows it
B32: 7 | C32: Which unit price is saved on an order line, and what does the order 'total' include? → assumed: The part's current price when the order is placed; total = subtotal + delivery charge
B33: 8 | C33: How are 'ORD-' + 6-digit order numbers generated? → assumed: Sequential from a database sequence, zero-padded (ORD-000001)
B34: 9 | C34: Should the delivery prices (£0 / £9.99), the stock thresholds (5) and the page size (20) be fixed in the code or set in configuration? → assumed: Fixed constants in the code
B35: 10 | C35: What happens if the order's status changes from Placed (e.g. to Packed) after the buyer opened it but before they confirm cancelling? → assumed: The API cancels only if the status is still Placed; otherwise it refuses, shows a message and refreshes the order
B36: 11 | C36: What happens if placing an order fails (network or server error)? → assumed: Show an error message, keep the cart and checkout details, and let the buyer try again
B37: 12 | C37: What happens when a quantity is set to 0, left blank, set above 99, or isn't a whole number? → assumed: Set it to the nearest value in range (blank or 0 becomes 1, above 99 becomes 99)
... B53: 28 | C53: Split before the build: EST-1, EST-3, EST-6, EST-13 (agent work over 16 h or very large is split into smaller tasks; the hours stay as estimated).
B56: S.No | C56: Risks
B57: 1 | C57: Estimates will increase in case of change in requirement

Sheet Other Estimates
B2: Other Estimates for Parts Quick Order
B3: 2026-10-05
B4: by mhamza
B6: GD
B7: Not in scope: no work in this estimate
B8: S.No | C8: Task | D8: Minimum | E8: Maximum | F8: Comments | G8: Executor | H8: Requirement id(s) | I8: Task id
B9: 1 | C9: None | D9: 0 | E9: 0
C10: GD TOTAL | D10: =SUM(D9:D9) -> 0 | E10: =SUM(E9:E9) -> 0
B13: PM
B14: S.No | C14: Task | D14: Minimum | E14: Maximum | F14: Comments | G14: Executor | H14: Requirement id(s) | I14: Task id
B15: 1 | C15: Project management: client liaison | D15: 4 | E15: 8 | F15: Client calls, scope decisions and sign-offs | G15: Human | I15: EST-25
C16: PM TOTAL | D16: =SUM(D15:D15) -> 4 | E16: =SUM(E15:E15) -> 8
B19: PDM
B20: S.No | C20: Task | D20: Minimum | E20: Maximum | F20: Comments | G20: Executor | H20: Requirement id(s) | I20: Task id
B21: 1 | C21: Handover notes | D21: 2.88 | E21: 5.76 | F21: Documentation delivers no requirement on its own | G21: Factory | I21: EST-26
C22: PDM TOTAL | D22: =SUM(D21:D21) -> 2.88 | E22: =SUM(E21:E21) -> 5.76
B25: Cross-cutting
B26: S.No | C26: Task | D26: Minimum | E26: Maximum | F26: Comments | G26: Executor | H26: Requirement id(s) | I26: Task id
B27: 1 | C27: None | D27: 0 | E27: 0
C28: Cross-cutting TOTAL | D28: =SUM(D27:D27) -> 0 | E28: =SUM(E27:E27) -> 0

Sheet All Tasks
B1: All tasks: Parts Quick Order
B2: Filter or sort any column. The Total row adds up only the rows the filter shows.
B4: Task id | C4: Task | D4: Track | E4: Module | F4: Executor | G4: Requirement id(s) | H4: Minimum | I4: Maximum
B5: EST-1 | C5: Environments, CI/CD and hosting for API and portal | D5: Backend | E5: Portal shell, navigation and cross-cutting | F5: Joint | H5: 17.47 | I5: 30.58
B6: EST-2 | C6: Orders data model, migrations and seed data | D6: Backend | E6: Placing orders (orders API) | F6: Factory | G6: REQ-20, REQ-28, REQ-30, REQ-38 | H6: 2.16 | I6: 4.32
B7: EST-3 | C7: Buyer identity from existing company login session | D7: Backend | E7: My orders | F7: Joint | G7: REQ-27, REQ-16 | H7: 13.1 | I7: 20.97
B8: EST-4 | C8: GET /api/parts: search, filters, paging, stock state | D8: Backend | E8: Find parts | F8: Factory | G8: REQ-2, REQ-3, REQ-4, REQ-5, REQ-38 | H8: 3.9 | I8: 7.8
B9: EST-5 | C9: GET /api/parts/brands | D9: Backend | E9: Find parts | F9: Factory | G9: REQ-5 | H9: 1.62 | I9: 3.24
B10: EST-6 | C10: POST /api/orders: place order rules | D10: Backend | E10: Placing orders (orders API) | F10: Factory | G10: REQ-20, REQ-21, REQ-22, REQ-25 | H10: 12.8 | I10: 22.4
B11: EST-7 | C11: GET /api/orders: buyer's orders list with status filter | D11: Backend | E11: My orders | F11: Factory | G11: REQ-27, REQ-28, REQ-29, REQ-35 | H11: 2.7 | I11: 5.4
B12: EST-8 | C12: GET /api/orders/{orderNumber}: order detail | D12: Backend | E12: My orders | F12: Factory | G12: REQ-27, REQ-30 | H12: 1.62 | I12: 3.24
B13: EST-9 | C13: POST /api/orders/{orderNumber}/cancel: cancel rules | D13: Backend | E13: My orders | F13: Factory | G13: REQ-33, REQ-34, REQ-27, REQ-25 | H13: 7.21 | I13: 12.61
B14: EST-10 | C14: Portal app shell (web) | D14: Web | E14: Portal shell, navigation and cross-cutting | F14: Factory | G14: REQ-1, REQ-9, REQ-36, REQ-37 | H14: 4.8 | I14: 8.4
B15: EST-11 | C15: CartStore in browser local storage per buyer | D15: Web | E15: Cart and checkout | F15: Factory | G15: REQ-8, REQ-9, REQ-10, REQ-11, REQ-12, REQ-13, REQ-14, REQ-15, REQ-16, REQ-19, REQ-39, REQ-41, REQ-42, REQ-43 | H15: 7.02 | I15: 11.7
B16: EST-12 | C16: Find parts screen (web) | D16: Web | E16: Find parts | F16: Factory | G16: REQ-1, REQ-2, REQ-3, REQ-4, REQ-5, REQ-6, REQ-7, REQ-8, REQ-9, REQ-10, REQ-36, REQ-37, REQ-38 | H16: 6 | I16: 10
B17: EST-13 | C17: Cart lines with live prices (web) | D17: Web | E17: Cart and checkout | F17: Factory | G17: REQ-9, REQ-11, REQ-12, REQ-13, REQ-14, REQ-15, REQ-17, REQ-41, REQ-42, REQ-43, REQ-36, REQ-37 | H17: 19.6 | I17: 30.8
... B25: EST-21 | C25: End-to-end test: find, add, check out, view and cancel | D25: QA | E25: Cart and checkout | F25: Factory | G25: REQ-1, REQ-4, REQ-8, REQ-9, REQ-18, REQ-20, REQ-23, REQ-28, REQ-30, REQ-32, REQ-33 | H25: 6 | I25: 10
B26: EST-22 | C26: Production release of API and portal | D26: Web | E26: Portal shell, navigation and cross-cutting | F26: Joint | H26: 6.55 | I26: 13.1
B27: EST-23 | C27: Client design review and approval | D27: Design | E27: Portal shell, navigation and cross-cutting | F27: Human | H27: 2 | I27: 4
B28: EST-24 | C28: Client acceptance testing | D28: QA | E28: Portal shell, navigation and cross-cutting | F28: Human | H28: 4 | I28: 8
B29: EST-25 | C29: Project management: client liaison | D29: PM | E29: Portal shell, navigation and cross-cutting | F29: Human | H29: 4 | I29: 8
B30: EST-26 | C30: Handover notes | D30: PDM | E30: Portal shell, navigation and cross-cutting | F30: Factory | H30: 2.88 | I30: 5.76
C31: Total (rows shown) | H31: =SUBTOTAL(9,H5:H30) -> 158.77 | I31: =SUBTOTAL(9,I5:I30) -> 279.72
