Workbook

Sheet Summary
B1: Folio3 Project Estimation
B2: Parts Quick Order
B3: Summary of Estimates
B5: Client Name | C5: Demo Garage
B6: Project Manager | C6: mhamza
B7: Date | C7: 2026-10-05
B8: Version | C8: 1
C9: Efforts (in hours)
B10: Task Summary | C10: Minimum | D10: Maximum | E10: Comments | H10: Avg | I10: Resources | J10: Weeks
B11: Backend Development Estimates | C11: ='Dev Backend Estimates'!D6 -> 25.58 | D11: ='Dev Backend Estimates'!E6 -> 42.81 | E11: Grand total of the Backend sheet | H11: =ROUND((C11+D11)/2,2) -> 34.2 | I11: 1 | J11: =ROUND(H11/($C$48*I11),2) -> 0.86
B12: Mobile Development Estimates | C12: ='Dev Mobile Estimates'!D6 -> 0 | D12: ='Dev Mobile Estimates'!E6 -> 0 | E12: Grand total of the Mobile sheet | H12: =ROUND((C12+D12)/2,2) -> 0 | I12: 1 | J12: =ROUND(H12/($C$48*I12),2) -> 0
B13: Admin Development Estimates | C13: ='Dev Web Estimates'!D6 -> 4.68 | D13: ='Dev Web Estimates'!E6 -> 9.36 | E13: Grand total of the Web / Admin sheet | H13: =ROUND((C13+D13)/2,2) -> 7.02 | I13: 1 | J13: =ROUND(H13/($C$48*I13),2) -> 0.18
B14: QA Estimates | C14: ='QA Estimates'!D6 -> 4 | D14: ='QA Estimates'!E6 -> 8 | E14: Grand total of the QA sheet | H14: =ROUND((C14+D14)/2,2) -> 6 | I14: 1 | J14: =ROUND(H14/($C$48*I14),2) -> 0.15
B15: GD Estimates | C15: ='Other Estimates'!D10 -> 0 | D15: ='Other Estimates'!E10 -> 0 | E15: Other Estimates sheet | H15: =ROUND((C15+D15)/2,2) -> 0 | I15: 1 | J15: =ROUND(H15/($C$48*I15),2) -> 0
B16: PM Estimates | C16: ='Other Estimates'!D16 -> 16 | D16: ='Other Estimates'!E16 -> 24 | E16: Other Estimates sheet | H16: =ROUND((C16+D16)/2,2) -> 20 | I16: 1 | J16: =ROUND(H16/($C$48*I16),2) -> 0.5
B17: PDM Estimates | C17: ='Other Estimates'!D22 -> 0 | D17: ='Other Estimates'!E22 -> 0 | E17: Other Estimates sheet | H17: =ROUND((C17+D17)/2,2) -> 0 | I17: 1 | J17: =ROUND(H17/($C$48*I17),2) -> 0
B18: Cross-cutting Estimates | C18: ='Other Estimates'!D28 -> 0 | D18: ='Other Estimates'!E28 -> 0 | E18: Other Estimates sheet: deployment, documentation and the like | H18: =ROUND((C18+D18)/2,2) -> 0 | I18: 1 | J18: =ROUND(H18/($C$48*I18),2) -> 0
B19: Design Estimates | C19: ='Design Estimates'!D6 -> 0 | D19: ='Design Estimates'!E6 -> 0 | E19: Counted in the total only when Design is switched on below | H19: =ROUND((C19+D19)/2,2) -> 0 | I19: 1 | J19: =ROUND(H19/($C$48*I19),2) -> 0
B20: Total | C20: =SUM(C11:C18)+IF($C$47="Yes",C19,0) -> 50.26 | D20: =SUM(D11:D18)+IF($C$47="Yes",D19,0) -> 84.17 | H20: =ROUND((C20+D20)/2,2) -> 67.22
B23: List of Special Considerations, where applicable:
B24: Tasks | C24: Action | E24: Comments
B25: Application type (mobile, desktop, web) | C25: Backend + Web | E25: From the tracks that have work
B26: Platforms/OS supported | C26: Not specified | E26: Confirm with the client
B27: Browsers supported | C27: Assumed: The latest two versions of Chrome, Edge, Safari and Firefox. | E27: Factory assumption ASM-17, confirm with the client
B28: Deployment (cloud, dedicated server, enterprise internal network) | C28: Not specified | E28: Confirm with the client
B29: Performance, Load requirements | C29: Assumed: Up to 1,000 users and 100,000 records in the first year. | E29: Factory assumption ASM-16, confirm with the client
B30: Security requirements | C30: Not specified | E30: Confirm with the client
B31: Documentation requirements | C31: Not specified | E31: Confirm with the client
B32: Other custom? | C32: No
B46: Parameters
B47: Include Design in total | C47: Yes
B48: Hours per week | C48: 40
B49: Feedback rounds | C49: 2
B50: Stack chosen by | C50: client
B51: Delivery model | C51: Solely agentic
B55: API credit cost (USD)
B56: Phase | C56: Min ($) | D56: Max ($)
B57: planning | C57: 0.64 | D57: 2.92
B58: design | C58: 0.05 | D58: 7.3
B59: breakdown-estimate | C59: 0.07 | D59: 0.09
...

Sheet Dev Backend Estimates
B2: Development Estimates for Parts Quick Order
B3: 2026-10-05
B4: by mhamza
C6: Grand Total (in hours) | D6: =D22+D27+D32 -> 25.58 | E6: =E22+E27+E32 -> 42.81 | F6: Sum of development, other activities and research efforts.
B8: S.No | C8: Task | D8: Minimum | E8: Maximum | F8: Comments | G8: Executor | H8: Requirement id(s) | I8: Task id
B9: 1 | C9: Portal shell, sign-in wiring, navigation, accessibility and responsive layout | D9: =SUM(D10:D11) -> 25.58 | E9: =SUM(E10:E11) -> 42.81
C10: Buyer identity from the existing company login session | D10: 13.1 | E10: 20.97 | F10: check the existing company login's session token or cookie on every API request; read the buyer ID from the session and pass it to the parts and orders APIs; expose the buyer ID to the portal for the per-buyer cart key; human step: get access to and details of the company login session format | G10: Joint | H10: REQ-27 | I10: EST-2
C11: Environments, CI/CD and monitoring | D11: 12.48 | E11: 21.84 | F11: Environment and pipeline setup; delivers no requirement directly | G11: Joint | I11: EST-19
B13: 2 | C13: Find parts (search, filters, paging, stock state, add to cart) | D13: =SUM(D14:D15) -> 0 | E13: =SUM(E14:E15) -> 0
C14: GET /api/parts: search, filters, paging, stock state | D14: 0 | E14: 0 | F14: sorted by name A–Z, 20 per page (fixed constant), page parameter, total count; fields: image (or null), name, partNumber, brand, price in GBP with 2 decimals, stockState, stock as a whole number; stockState: "In stock" at 5 or more, "Low stock (n left)" at 1–4, "Out of stock" at 0; q: case-insensitive contains on name or part number, applied only at 2+ characters; category and brand filters, one each, "All" means no filter, combined with q; no match returns 200 with an empty list and total 0; p95 under 500 ms with 5,000 parts | G14: Factory | H14: REQ-2, REQ-3, REQ-4, REQ-5, REQ-7, REQ-38 | I14: EST-3
C15: GET /api/parts/brands: brand list from parts data | D15: 0 | E15: 0 | F15: distinct brands taken from the parts data, sorted | G15: Factory | H15: REQ-5 | I15: EST-4
B17: 3 | C17: Checkout and placing an order | D17: =SUM(D18:D20) -> 0 | E17: =SUM(E18:E20) -> 0
C18: Data model: orders, order lines, order number sequence, parts indexes and seed data | D18: 0 | E18: 0 | F18: orders table in the existing PostgreSQL database: buyer ID, order number, date placed, delivery address, delivery option (STANDARD/NEXT_DAY), total, status; order_lines table: order, part number (refers to parts by part number), quantity, unit price; status values Placed, Packed, Dispatched, Delivered, Cancelled; database sequence for ORD- + 6 zero-padded digits (ORD-000001); indexes on orders (buyer ID, date placed, status) for 100,000 records; indexes on parts name / part number / category / brand for search with 5,000 parts; seed of 5,000 parts for performance testing; migrations | G18: Factory | H18: REQ-20, REQ-28, REQ-38 | I18: EST-1
C19: Orders API: create with validation, list, detail, scoped to the buyer | D19: 0 | E19: 0 | F19: POST /api/orders returns 201 with orderNumber, status Placed, total; 400 with an error field naming the input for: no lines, quantity outside 1–99, unknown part number, address outside 5–200 characters, missing or unknown delivery option; no order saved; GET /api/orders: only the buyer's orders, newest first, with orderNumber, datePlaced, itemCount (total of quantities), total, status; GET /api/orders?status=: status filter; empty list with 200 when the buyer has no orders; GET /api/orders/{orderNumber}: lines (part number, name, quantity, unit price), address, delivery option, total, status; 404 for another buyer's order | G19: Factory | H19: REQ-20, REQ-21, REQ-27, REQ-28, REQ-29, REQ-30, REQ-35 | I19: EST-5
C20: Order rules: pricing, totals, numbering, stock check, cancel state machine | D20: 0 | E20: 0 | F20: unit price = the part's current price when placed; any price sent by the client is ignored; total = subtotal + delivery charge (Standard £0.00, Next day £9.99, fixed constants); sequential order number ORD-000001, ORD-000002 … from the sequence; stock check at placement: 409 listing each affected part number with available stock; no order saved (transaction); stock quantity in parts never changed on place or cancel; POST /api/orders/{orderNumber}/cancel: sets Cancelled and returns 200 only if still Placed (conditional update); 409 with an error message when no longer Placed, status left unchanged; 404 when cancelling another buyer's order | G20: Factory | H20: REQ-20, REQ-22, REQ-25, REQ-27, REQ-33, REQ-34 | I20: EST-6
C22: Development Total Efforts (in hours) | D22: =D9+D13+D17 -> 25.58 | E22: =E9+E13+E17 -> 42.81
B25: S.No | C25: Other Development Activities | D25: Minimum | E25: Maximum | F25: Comments | G25: Executor | H25: Requirement id(s) | I25: Task id
B26: 1 | C26: None | D26: 0 | E26: 0
C27: Post Development Activities Total Efforts (in hours) | D27: =SUM(D26:D26) -> 0 | E27: =SUM(E26:E26) -> 0
B30: S.No | C30: Research Task (if any) | D30: Minimum | E30: Maximum | F30: Comments | G30: Executor | H30: Requirement id(s) | I30: Task id
B31: 1 | C31: None | D31: 0 | E31: 0 | F31: No research task in this estimate
C32: Research Total Efforts (in hours) | D32: =SUM(D31:D31) -> 0 | E32: =SUM(E31:E31) -> 0
B35: S.No | C35: Assumptions & Constraints
B36: 1 | C36: Does the 'Place order' button also need the cart to have at least one line, or is that already covered because checkout is hidden when the cart is empty? → assumed: Covered already: checkout is hidden when the cart is empty, and the API also refuses an order with no lines
B37: 2 | C37: Does placing (or cancelling) an order change the stock quantity in the existing parts database? → assumed: No: stock is read-only and orders never change it
B38: 3 | C38: What happens when a cart quantity is more than the current stock (or the part is now out of stock) at the moment the buyer presses 'Place order'? → assumed: The API checks stock again, rejects the order, lowers the affected lines to the stock now available with 'Only n available', and keeps the cart
B39: 4 | C39: Where is the cart kept? → assumed: In the browser's local storage for the signed-in buyer (kept across page reloads on the same device)
B40: 5 | C40: How does the API find out which buyer is making a request through the existing company login? → assumed: The API checks the existing company login's session token or cookie and reads the buyer ID from it
B41: 6 | C41: Nothing in this work moves an order to Packed, Dispatched or Delivered (no admin screens, no integrations). How do statuses change after Placed? → assumed: Staff update the status directly in the database, outside this work; the portal only shows it
B42: 7 | C42: Which unit price is saved on an order line, and what does the order 'total' include? → assumed: The part's current price when the order is placed; total = subtotal + delivery charge
B43: 8 | C43: How are 'ORD-' + 6-digit order numbers generated? → assumed: Sequential from a database sequence, zero-padded (ORD-000001)
B44: 9 | C44: Should the delivery prices (£0 / £9.99), the stock thresholds (5) and the page size (20) be fixed in the code or set in configuration? → assumed: Fixed constants in the code
B45: 10 | C45: What happens if the order's status changes from Placed (e.g. to Packed) after the buyer opened it but before they confirm cancelling? → assumed: The API cancels only if the status is still Placed; otherwise it refuses, shows a message and refreshes the order
B46: 11 | C46: What happens if placing an order fails (network or server error)? → assumed: Show an error message, keep the cart and checkout details, and let the buyer try again
B47: 12 | C47: What happens when a quantity is set to 0, left blank, set above 99, or isn't a whole number? → assumed: Set it to the nearest value in range (blank or 0 becomes 1, above 99 becomes 99)
... B63: 28 | C63: Split before the build: EST-2, EST-5, EST-8, EST-19 (agent work over 16 h or very large is split into smaller tasks; the hours stay as estimated).
B66: S.No | C66: Risks
B67: 1 | C67: Estimates will increase in case of change in requirement

Sheet Dev Mobile Estimates
B2: Development Estimates for Parts Quick Order
B3: 2026-10-05
B4: by mhamza
B5: Not in scope: no work in this estimate
C6: Grand Total (in hours) | D6: =D11+D16+D21 -> 0 | E6: =E11+E16+E21 -> 0 | F6: Sum of development, other activities and research efforts.
B8: S.No | C8: Task | D8: Minimum | E8: Maximum | F8: Comments | G8: Executor | H8: Requirement id(s) | I8: Task id
C9: None | D9: 0 | E9: 0
C11: Development Total Efforts (in hours) | D11: =D9 -> 0 | E11: =E9 -> 0
B14: S.No | C14: Other Development Activities | D14: Minimum | E14: Maximum | F14: Comments | G14: Executor | H14: Requirement id(s) | I14: Task id
B15: 1 | C15: None | D15: 0 | E15: 0
C16: Post Development Activities Total Efforts (in hours) | D16: =SUM(D15:D15) -> 0 | E16: =SUM(E15:E15) -> 0
B19: S.No | C19: Research Task (if any) | D19: Minimum | E19: Maximum | F19: Comments | G19: Executor | H19: Requirement id(s) | I19: Task id
B20: 1 | C20: None | D20: 0 | E20: 0 | F20: No research task in this estimate
C21: Research Total Efforts (in hours) | D21: =SUM(D20:D20) -> 0 | E21: =SUM(E20:E20) -> 0

Sheet Dev Web Estimates
B2: Development Estimates for Parts Quick Order
B3: 2026-10-05
B4: by mhamza
C6: Grand Total (in hours) | D6: =D26+D31+D36 -> 4.68 | E6: =E26+E31+E36 -> 9.36 | F6: Sum of development, other activities and research efforts.
B8: S.No | C8: Task | D8: Minimum | E8: Maximum | F8: Comments | G8: Executor | H8: Requirement id(s) | I8: Task id
B9: 1 | C9: Portal shell, sign-in wiring, navigation, accessibility and responsive layout | D9: =SUM(D10:D11) -> 4.68 | E9: =SUM(E10:E11) -> 9.36
C10: Web app shell: routes, header with links and cart count, layout, session wiring | D10: 0 | E10: 0 | F10: routes /parts, /cart, /orders (exactly three screens); header links to the other two screens on each screen; header cart count = total of all quantities, updated live without reload; company login session wiring and buyer ID; responsive layout with no horizontal scroll at 360, 768, 1280 px; visible focus styles and keyboard navigation; shared GBP formatter (£ with 2 decimals), English-only copy; shared toast and inline alert components; error page / unknown route | G10: Factory | H10: REQ-1, REQ-9, REQ-36, REQ-37 | I10: EST-7
C11: Production release | D11: 4.68 | E11: 9.36 | F11: Production launch; delivers no requirement directly | G11: Joint | I11: EST-20
B13: 2 | C13: Find parts (search, filters, paging, stock state, add to cart) | D13: =SUM(D14:D14) -> 0 | E13: =SUM(E14:E14) -> 0
C14: Find parts screen (S-1) | D14: 0 | E14: 0 | F14: search box by name or part number with hint "Type at least 2 characters…"; Category and Brand filters, one each with All; brands loaded from /api/parts/brands; result rows: image, name, part no., brand, £ price, stock badge in text; Previous/Next page with "page x of y" and count; back to page 1 when search or filter changes; Add to cart button, disabled for out-of-stock parts; header count bumps after add; Go to cart (n) link; states: loading skeleton rows, empty "No parts match" with Clear search and filters button, error with Try again, low stock badge, added confirmation; first page shown within 2 s with 5,000 parts | G14: Factory | H14: REQ-2, REQ-3, REQ-4, REQ-5, REQ-6, REQ-7, REQ-8, REQ-9, REQ-10, REQ-38 | I14: EST-9
B16: 3 | C16: Cart (lines, quantities, local storage, live price and stock refresh) | D16: =SUM(D17:D17) -> 0 | E16: =SUM(E17:E17) -> 0
C17: Cart and checkout screen (S-2), part 1: cart lines and CartStore | D17: 0 | E17: 0 | F17: CartStore kept in local storage under the signed-in buyer's ID; addPart: add a line with quantity 1 or add 1 to it; nothing for out-of-stock parts; capped at stock with "Only n available"; cart table: part, part no., unit price, editable quantity, line total, Remove; line total = unit price × quantity; line and order totals recalculated at once; quantity correction: blank/0 → 1, above 99 → 99, decimals rounded; quantity above stock set to stock with "Only n available" next to the line; removeLine and count(); refresh on open: fetch current prices and stock from the parts API; use only current prices; line with 0 stock removed with "<part name> is now out of stock" alert; price fetch failure: lines without prices or totals, error message, Try again, checkout hidden; applyStockLimits for a 409: lower lines to available stock, remove lines with 0 available, keep other lines; states: loading prices, empty "Your cart is empty" with link to Find parts and checkout hidden; unit tests for CartStore acceptance criteria | G17: Factory | H17: REQ-8, REQ-10, REQ-11, REQ-12, REQ-13, REQ-14, REQ-15, REQ-16, REQ-17, REQ-39, REQ-41, REQ-42, REQ-43 | I17: EST-8
B19: 4 | C19: Checkout and placing an order | D19: =SUM(D20:D20) -> 0 | E19: =SUM(E20:E20) -> 0
C20: Cart and checkout screen (S-2), part 2: checkout form and placing the order | D20: 0 | E20: 0 | F20: Delivery address textarea, 5–200 characters, empty each time, with label and error "Enter a delivery address of 5 to 200 characters"; Delivery option radio Standard · £0.00 / Next day · £9.99 with error "Choose Standard or Next day"; Order summary: items, subtotal, delivery charge, total; CheckoutForm.canPlaceOrder: Place order enabled only with a valid address and an option chosen; startSubmit/finishSubmit: Place order disabled while the request runs; exactly one POST; success: show the new order number, empty the cart, link to My orders; 409 conflict: apply stock limits to the cart and show messages; network error toast "Connection lost. Check My orders before you try again."; cart, address and option kept; server error toast "Order not placed: server error. Your cart and details are kept."; unit tests for CheckoutForm | G20: Factory | H20: REQ-18, REQ-19, REQ-20, REQ-21, REQ-22, REQ-23, REQ-24, REQ-39, REQ-40 | I20: EST-10
B22: 5 | C22: My orders (list, status filter, detail panel, timeline, cancel) | D22: =SUM(D23:D24) -> 0 | E22: =SUM(E23:E24) -> 0
C23: My orders screen (S-3), part 1: orders table with status filter | D23: 0 | E23: 0 | F23: table: order, placed date, items, total, status (text), newest first; status filter chips: All statuses, Placed, Packed, Dispatched, Delivered, Cancelled; View order opens the detail panel on the same /orders page (Enter key); states: loading skeleton rows, empty "No orders yet" with link to Find parts, filtered empty, error with Try again | G23: Factory | H23: REQ-1, REQ-28, REQ-29, REQ-35 | I23: EST-11
C24: My orders screen (S-3), part 2: order detail drawer, timeline and cancel | D24: 0 | E24: 0 | F24: drawer overlay: order number, date placed, lines (part number, name, qty, unit price, amount), delivery address, delivery option, total, status; timeline Placed → Packed → Dispatched → Delivered with the current step marked by text as well as colour; Cancel order button only while Placed; confirm dialog "Cancel ORD-…?" with Yes, cancel order / Keep order; no request sent when kept; success toast; status becomes Cancelled and the button is hidden; 409 refusal toast "Couldn't cancel: … has already been packed.", panel refreshes; focus handling for drawer and dialog by keyboard | G24: Factory | H24: REQ-1, REQ-30, REQ-31, REQ-32, REQ-33, REQ-34 | I24: EST-12
C26: Development Total Efforts (in hours) | D26: =D9+D13+D16+D19+D22 -> 4.68 | E26: =E9+E13+E16+E19+E22 -> 9.36
B29: S.No | C29: Other Development Activities | D29: Minimum | E29: Maximum | F29: Comments | G29: Executor | H29: Requirement id(s) | I29: Task id
B30: 1 | C30: None | D30: 0 | E30: 0
C31: Post Development Activities Total Efforts (in hours) | D31: =SUM(D30:D30) -> 0 | E31: =SUM(E30:E30) -> 0
B34: S.No | C34: Research Task (if any) | D34: Minimum | E34: Maximum | F34: Comments | G34: Executor | H34: Requirement id(s) | I34: Task id
B35: 1 | C35: None | D35: 0 | E35: 0 | F35: No research task in this estimate
C36: Research Total Efforts (in hours) | D36: =SUM(D35:D35) -> 0 | E36: =SUM(E35:E35) -> 0
B39: S.No | C39: Assumptions & Constraints
B40: 1 | C40: Does the 'Place order' button also need the cart to have at least one line, or is that already covered because checkout is hidden when the cart is empty? → assumed: Covered already: checkout is hidden when the cart is empty, and the API also refuses an order with no lines
B41: 2 | C41: Does placing (or cancelling) an order change the stock quantity in the existing parts database? → assumed: No: stock is read-only and orders never change it
B42: 3 | C42: What happens when a cart quantity is more than the current stock (or the part is now out of stock) at the moment the buyer presses 'Place order'? → assumed: The API checks stock again, rejects the order, lowers the affected lines to the stock now available with 'Only n available', and keeps the cart
B43: 4 | C43: Where is the cart kept? → assumed: In the browser's local storage for the signed-in buyer (kept across page reloads on the same device)
B44: 5 | C44: How does the API find out which buyer is making a request through the existing company login? → assumed: The API checks the existing company login's session token or cookie and reads the buyer ID from it
B45: 6 | C45: Nothing in this work moves an order to Packed, Dispatched or Delivered (no admin screens, no integrations). How do statuses change after Placed? → assumed: Staff update the status directly in the database, outside this work; the portal only shows it
B46: 7 | C46: Which unit price is saved on an order line, and what does the order 'total' include? → assumed: The part's current price when the order is placed; total = subtotal + delivery charge
B47: 8 | C47: How are 'ORD-' + 6-digit order numbers generated? → assumed: Sequential from a database sequence, zero-padded (ORD-000001)
B48: 9 | C48: Should the delivery prices (£0 / £9.99), the stock thresholds (5) and the page size (20) be fixed in the code or set in configuration? → assumed: Fixed constants in the code
B49: 10 | C49: What happens if the order's status changes from Placed (e.g. to Packed) after the buyer opened it but before they confirm cancelling? → assumed: The API cancels only if the status is still Placed; otherwise it refuses, shows a message and refreshes the order
B50: 11 | C50: What happens if placing an order fails (network or server error)? → assumed: Show an error message, keep the cart and checkout details, and let the buyer try again
B51: 12 | C51: What happens when a quantity is set to 0, left blank, set above 99, or isn't a whole number? → assumed: Set it to the nearest value in range (blank or 0 becomes 1, above 99 becomes 99)
... B67: 28 | C67: Split before the build: EST-2, EST-5, EST-8, EST-19 (agent work over 16 h or very large is split into smaller tasks; the hours stay as estimated).
B70: S.No | C70: Risks
B71: 1 | C71: Estimates will increase in case of change in requirement

Sheet QA Estimates
B2: QA Estimates for Parts Quick Order
B3: 2026-10-05
B4: by mhamza
C6: Grand Total Efforts (in hours) | D6: =D24 -> 4 | E6: =E24 -> 8 | F6: Sum of QA and Misc.
B8: S.No | C8: Estimation Summary | D8: Minimum | E8: Maximum | F8: Comments | G8: Executor | H8: Requirement id(s) | I8: Task id
B9: 1 | C9: Test Plan/Strategy | D9: 0 | E9: 0 | F9: Test planning, with the test plan, strategy and traceability matrix as outputs. Not sized in this estimate
B10: 2 | C10: Set up of Test Environments | D10: 0 | E10: 0 | F10: Setting up code and white box test environments. Not sized in this estimate
B11: 3 | C11: Validation and Smoke test cases | D11: =SUM(D12:D15) -> 0 | E11: =SUM(E12:E15) -> 0 | F11: Test cases to execute while debugging and white box testing
C12: Test cases: Find parts, including performance | D12: 0 | E12: 0 | F12: API cases AC-2.x, AC-3.x, AC-4.x, AC-5.x, AC-7.1; manual cases AC-6.1, AC-7.2, AC-9.2, AC-10.2; AC-38.1 p95 under 500 ms with 5,000 parts; AC-38.2 first page within 2 s; NFR-1 load check at 1,000 concurrent users | G12: Factory | H12: REQ-2, REQ-3, REQ-4, REQ-5, REQ-6, REQ-7, REQ-8, REQ-9, REQ-10, REQ-38 | I12: EST-14
C13: Test cases: Cart | D13: 0 | E13: 0 | F13: manual cases AC-12.2, AC-14.2, AC-17.1, AC-41.2, AC-43.4, AC-43.5; check that unit cases for CartStore are covered | G13: Factory | H13: REQ-11, REQ-12, REQ-13, REQ-14, REQ-15, REQ-16, REQ-17, REQ-39, REQ-41, REQ-42, REQ-43 | I13: EST-15
C14: Test cases: Checkout and placing orders | D14: 0 | E14: 0 | F14: API cases AC-20.x, AC-21.x, AC-22.1, AC-25.1; manual cases AC-18.3, AC-23.1, AC-24.1, AC-24.2, AC-40.3 | G14: Factory | H14: REQ-18, REQ-19, REQ-20, REQ-21, REQ-22, REQ-23, REQ-24, REQ-25, REQ-40 | I14: EST-16
C15: Test cases: My orders | D15: 0 | E15: 0 | F15: API cases AC-27.x, AC-28.1, AC-29.1, AC-30.1, AC-33.1, AC-34.1, AC-35.1; manual cases AC-31.1, AC-32.1, AC-32.2, AC-34.2, AC-35.2 | G15: Factory | H15: REQ-27, REQ-28, REQ-29, REQ-30, REQ-31, REQ-32, REQ-33, REQ-34, REQ-35 | I15: EST-17
B16: 4 | C16: Validation testing | D16: =SUM(D17:D17) -> 0 | E16: =SUM(E17:E17) -> 0 | F16: Testing cycles; the detail is below
C17: Testing Cycle 1 | D17: =D30 -> 0 | E17: =E30 -> 0
B18: 5 | C18: Smoke testing | D18: 0 | E18: 0 | F18: Smoke testing after each deployment, including preparation. Not sized in this estimate
B19: 6 | C19: Multi Browser Compatibility testing | D19: =SUM(D20:D20) -> 0 | E19: =SUM(E20:E20) -> 0 | F19: Browser, OS and device compatibility
C20: Test cases: navigation, accessibility, responsive layout, browsers | D20: 0 | E20: 0 | F20: AC-1.1, AC-1.2; AC-36.1 at 360/768/1280 px on the latest 2 versions of Chrome, Edge, Safari, Firefox; AC-37.1 keyboard-only run with a screen reader; axe scan of each screen: 0 serious or critical violations; stock and status indicators carry text | G20: Factory | H20: REQ-1, REQ-36, REQ-37 | I20: EST-13
B21: 7 | C21: UAT | D21: =SUM(D22:D22) -> 4 | E21: =SUM(E22:E22) -> 8 | F21: Client user acceptance testing support
C22: Client acceptance testing | D22: 4 | E22: 8 | F22: Client UAT of the finished portal; delivers no requirement directly | G22: Human | I22: EST-21
B23: 8 | C23: Misc. Optional testing | D23: 0 | E23: 0 | F23: Other testing named in the breakdown, and supervisor gate time. Not sized in this estimate
C24: Total QA Efforts | D24: =D9+D10+D11+D16+D18+D19+D21+D23 -> 4 | E24: =E9+E10+E11+E16+E18+E19+E21+E23 -> 8 | F24: Total hours of QA
B27: S.No | C27: Validation Testing | D27: Minimum | E27: Maximum | F27: Comments | G27: Executor | H27: Requirement id(s) | I27: Task id
C28: Testing Cycle 1
B29: 1 | C29: Automated end-to-end test: search to order to cancel | D29: 0 | E29: 0 | F29: search and filter, add to cart, header count updates; change quantity, enter address, choose delivery, place order, order number shown, cart emptied; open the order in My orders, cancel with confirmation, status Cancelled | G29: Factory | H29: REQ-4, REQ-5, REQ-8, REQ-9, REQ-18, REQ-20, REQ-23, REQ-28, REQ-30, REQ-32, REQ-33 | I29: EST-18
C30: Total Testing Cycle 1 | D30: =D29 -> 0 | E30: =E29 -> 0 | F30: Sum of testing cycle 1
B33: S.No | C33: Assumptions & Constraints
B34: 1 | C34: Does the 'Place order' button also need the cart to have at least one line, or is that already covered because checkout is hidden when the cart is empty? → assumed: Covered already: checkout is hidden when the cart is empty, and the API also refuses an order with no lines
B35: 2 | C35: Does placing (or cancelling) an order change the stock quantity in the existing parts database? → assumed: No: stock is read-only and orders never change it
B36: 3 | C36: What happens when a cart quantity is more than the current stock (or the part is now out of stock) at the moment the buyer presses 'Place order'? → assumed: The API checks stock again, rejects the order, lowers the affected lines to the stock now available with 'Only n available', and keeps the cart
B37: 4 | C37: Where is the cart kept? → assumed: In the browser's local storage for the signed-in buyer (kept across page reloads on the same device)
B38: 5 | C38: How does the API find out which buyer is making a request through the existing company login? → assumed: The API checks the existing company login's session token or cookie and reads the buyer ID from it
B39: 6 | C39: Nothing in this work moves an order to Packed, Dispatched or Delivered (no admin screens, no integrations). How do statuses change after Placed? → assumed: Staff update the status directly in the database, outside this work; the portal only shows it
B40: 7 | C40: Which unit price is saved on an order line, and what does the order 'total' include? → assumed: The part's current price when the order is placed; total = subtotal + delivery charge
B41: 8 | C41: How are 'ORD-' + 6-digit order numbers generated? → assumed: Sequential from a database sequence, zero-padded (ORD-000001)
B42: 9 | C42: Should the delivery prices (£0 / £9.99), the stock thresholds (5) and the page size (20) be fixed in the code or set in configuration? → assumed: Fixed constants in the code
B43: 10 | C43: What happens if the order's status changes from Placed (e.g. to Packed) after the buyer opened it but before they confirm cancelling? → assumed: The API cancels only if the status is still Placed; otherwise it refuses, shows a message and refreshes the order
B44: 11 | C44: What happens if placing an order fails (network or server error)? → assumed: Show an error message, keep the cart and checkout details, and let the buyer try again
B45: 12 | C45: What happens when a quantity is set to 0, left blank, set above 99, or isn't a whole number? → assumed: Set it to the nearest value in range (blank or 0 becomes 1, above 99 becomes 99)
... B61: 28 | C61: Split before the build: EST-2, EST-5, EST-8, EST-19 (agent work over 16 h or very large is split into smaller tasks; the hours stay as estimated).
B64: S.No | C64: Risks
...

Sheet Design Estimates
B2: Design Estimates for Parts Quick Order
B3: 2026-10-05
B4: by mhamza
B5: Not in scope: no work in this estimate
C6: Grand Total (in hours) | D6: =D11+D16+D21 -> 0 | E6: =E11+E16+E21 -> 0 | F6: Sum of development, other activities and research efforts.
B8: S.No | C8: Task | D8: Minimum | E8: Maximum | F8: Comments | G8: Executor | H8: Requirement id(s) | I8: Task id
C9: None | D9: 0 | E9: 0
C11: Development Total Efforts (in hours) | D11: =D9 -> 0 | E11: =E9 -> 0
B14: S.No | C14: Other Development Activities | D14: Minimum | E14: Maximum | F14: Comments | G14: Executor | H14: Requirement id(s) | I14: Task id
B15: 1 | C15: None | D15: 0 | E15: 0
C16: Post Development Activities Total Efforts (in hours) | D16: =SUM(D15:D15) -> 0 | E16: =SUM(E15:E15) -> 0
B19: S.No | C19: Research Task (if any) | D19: Minimum | E19: Maximum | F19: Comments | G19: Executor | H19: Requirement id(s) | I19: Task id
B20: 1 | C20: None | D20: 0 | E20: 0 | F20: No research task in this estimate
C21: Research Total Efforts (in hours) | D21: =SUM(D20:D20) -> 0 | E21: =SUM(E20:E20) -> 0

Sheet Other Estimates
B2: Other Estimates for Parts Quick Order
B3: 2026-10-05
B4: by mhamza
B6: GD
B7: Not in scope: no work in this estimate
B8: S.No | C8: Task | D8: Minimum | E8: Maximum | F8: Comments | G8: Executor | H8: Requirement id(s) | I8: Task id
B9: 1 | C9: None | D9: 0 | E9: 0
C10: GD TOTAL | D10: =SUM(D9:D9) -> 0 | E10: =SUM(E9:E9) -> 0
B13: PM
B14: S.No | C14: Task | D14: Minimum | E14: Maximum | F14: Comments | G14: Executor | H14: Requirement id(s) | I14: Task id
B15: 1 | C15: Project management | D15: 16 | E15: 24 | F15: Project management across the build; delivers no requirement directly | G15: Human | I15: EST-22
C16: PM TOTAL | D16: =SUM(D15:D15) -> 16 | E16: =SUM(E15:E15) -> 24
B19: PDM
B20: S.No | C20: Task | D20: Minimum | E20: Maximum | F20: Comments | G20: Executor | H20: Requirement id(s) | I20: Task id
B21: 1 | C21: Handover notes | D21: 0 | E21: 0 | F21: Documentation for the client's team; delivers no requirement directly | G21: Factory | I21: EST-23
C22: PDM TOTAL | D22: =SUM(D21:D21) -> 0 | E22: =SUM(E21:E21) -> 0
B25: Cross-cutting
B26: S.No | C26: Task | D26: Minimum | E26: Maximum | F26: Comments | G26: Executor | H26: Requirement id(s) | I26: Task id
B27: 1 | C27: None | D27: 0 | E27: 0
C28: Cross-cutting TOTAL | D28: =SUM(D27:D27) -> 0 | E28: =SUM(E27:E27) -> 0
