Workbook

Sheet Summary
B1: Folio3 Project Estimation
B2: Maintenance Request
B3: Summary of Estimates
B5: Client Name | C5: The ignite studio
B6: Project Manager | C6: Ahsan Raza
B7: Date | C7: 2026-10-10
B8: Version | C8: 1
C9: Efforts (in hours) | F9: API credits (USD)
B10: Task Summary | C10: Minimum | D10: Maximum | E10: Comments | F10: API min ($) | G10: API max ($) | H10: Avg | I10: Resources | J10: Weeks
B11: Backend Development Estimates | C11: ='Dev Backend Estimates'!D6 -> 27.26 | D11: ='Dev Backend Estimates'!E6 -> 49.73 | E11: Grand total of the Backend sheet | F11: ='Dev Backend Estimates'!J6 -> 4.58 | G11: ='Dev Backend Estimates'!K6 -> 21.95 | H11: =ROUND((C11+D11)/2,2) -> 38.49 | I11: 1 | J11: =ROUND(H11/($C$48*I11),2) -> 0.96
B12: Mobile Development Estimates | C12: ='Dev Mobile Estimates'!D6 -> 0 | D12: ='Dev Mobile Estimates'!E6 -> 0 | E12: Grand total of the Mobile sheet | F12: ='Dev Mobile Estimates'!J6 -> 0 | G12: ='Dev Mobile Estimates'!K6 -> 0 | H12: =ROUND((C12+D12)/2,2) -> 0 | I12: 1 | J12: =ROUND(H12/($C$48*I12),2) -> 0
B13: Admin Development Estimates | C13: ='Dev Web Estimates'!D6 -> 35.26 | D13: ='Dev Web Estimates'!E6 -> 59.28 | E13: Grand total of the Web / Admin sheet | F13: ='Dev Web Estimates'!J6 -> 5.61 | G13: ='Dev Web Estimates'!K6 -> 26.94 | H13: =ROUND((C13+D13)/2,2) -> 47.27 | I13: 1 | J13: =ROUND(H13/($C$48*I13),2) -> 1.18
B14: QA Estimates | C14: ='QA Estimates'!D6 -> 13 | D14: ='QA Estimates'!E6 -> 24.2 | E14: Grand total of the QA sheet | F14: ='QA Estimates'!J6 -> 1.49 | G14: ='QA Estimates'!K6 -> 7.18 | H14: =ROUND((C14+D14)/2,2) -> 18.6 | I14: 1 | J14: =ROUND(H14/($C$48*I14),2) -> 0.47
B15: GD Estimates | C15: ='Other Estimates'!D10 -> 0 | D15: ='Other Estimates'!E10 -> 0 | E15: Other Estimates sheet | F15: ='Other Estimates'!J10 -> 0 | G15: ='Other Estimates'!K10 -> 0 | H15: =ROUND((C15+D15)/2,2) -> 0 | I15: 1 | J15: =ROUND(H15/($C$48*I15),2) -> 0
B16: PM Estimates | C16: ='Other Estimates'!D16 -> 4 | D16: ='Other Estimates'!E16 -> 8 | E16: Other Estimates sheet | F16: ='Other Estimates'!J16 -> 0 | G16: ='Other Estimates'!K16 -> 0 | H16: =ROUND((C16+D16)/2,2) -> 6 | I16: 1 | J16: =ROUND(H16/($C$48*I16),2) -> 0.15
B17: PDM Estimates | C17: ='Other Estimates'!D23 -> 0 | D17: ='Other Estimates'!E23 -> 0 | E17: Other Estimates sheet | F17: ='Other Estimates'!J23 -> 0 | G17: ='Other Estimates'!K23 -> 0 | H17: =ROUND((C17+D17)/2,2) -> 0 | I17: 1 | J17: =ROUND(H17/($C$48*I17),2) -> 0
B18: Cross-cutting Estimates | C18: ='Other Estimates'!D29 -> 0 | D18: ='Other Estimates'!E29 -> 0 | E18: Other Estimates sheet: deployment, documentation and the like | F18: ='Other Estimates'!J29 -> 0 | G18: ='Other Estimates'!K29 -> 0 | H18: =ROUND((C18+D18)/2,2) -> 0 | I18: 1 | J18: =ROUND(H18/($C$48*I18),2) -> 0
B19: Design Estimates | C19: ='Design Estimates'!D6 -> 0 | D19: ='Design Estimates'!E6 -> 0 | E19: Counted in the total only when Design is switched on below | F19: ='Design Estimates'!J6 -> 0 | G19: ='Design Estimates'!K6 -> 0 | H19: =ROUND((C19+D19)/2,2) -> 0 | I19: 1 | J19: =ROUND(H19/($C$48*I19),2) -> 0
B20: Total | C20: =SUM(C11:C18)+IF($C$47="Yes",C19,0) -> 79.52 | D20: =SUM(D11:D18)+IF($C$47="Yes",D19,0) -> 141.21 | F20: =SUM(F11:F19)+F21 -> 12.66 | G20: =SUM(G11:G19)+G21 -> 64.09 | H20: =ROUND((C20+D20)/2,2) -> 110.37
B21: Project-level API (planning, design, breakdown and estimate, once per project) | F21: 0.98 | G21: 8.02
B23: List of Special Considerations, where applicable:
B24: Tasks | C24: Action | E24: Comments
B25: Application type (mobile, desktop, web) | C25: Backend + Web | E25: From the tracks that have work
B26: Platforms/OS supported | C26: Not specified | E26: Confirm with the client
B27: Browsers supported | C27: No specific browser support target beyond browsers compatible with the chosen implementation. | E27: Clarify answer Q-2
B28: Deployment (cloud, dedicated server, enterprise internal network) | C28: Not specified | E28: Confirm with the client
B29: Performance, Load requirements | C29: Not specified | E29: Confirm with the client
B30: Security requirements | C30: Not specified | E30: Confirm with the client
B31: Documentation requirements | C31: Not specified | E31: Confirm with the client
B32: Other custom? | C32: No
B46: Parameters
B47: Include Design in total | C47: Yes
B48: Hours per week | C48: 40
B49: Feedback rounds | C49: 2
B50: Stack chosen by | C50: undecided
B51: Delivery model | C51: Solely agentic
B52: Size band | C52: M
B55: API credit cost (USD)
B56: Phase | C56: Min ($) | D56: Max ($) | E56: Based on
B57: planning | C57: 0.51 | D57: 7.07 | E57: measured: p10-p90 of 8 runs (8 ledger)
...

Sheet Dev Backend Estimates
B2: Development Estimates for Maintenance Request
B3: 2026-10-10
B4: by Ahsan Raza
C6: Grand Total (in hours) | D6: =D16+D21+D26 -> 27.26 | E6: =E16+E21+E26 -> 49.73 | F6: Sum of development, other activities and research efforts. | I6: API total ($) | J6: =J16+J21+J26 -> 4.58 | K6: =K16+K21+K26 -> 21.95
B8: S.No | C8: Task | D8: Minimum | E8: Maximum | F8: Comments | G8: Executor | H8: Requirement id(s) | I8: Task id | J8: API min ($) | K8: API max ($)
B9: 1 | C9: Request data and HTTP API | D9: =SUM(D10:D14) -> 27.26 | E9: =SUM(E10:E14) -> 49.73 | J9: =SUM(J10:J14) -> 4.58 | K9: =SUM(K10:K14) -> 21.95
C10: Request data model, migrations, persistence, and seed data | D10: 2.88 | E10: 5.76 | F10: Request record fields: ID, title, area, priority, optional description, status, and UTC creation time; Database migrations for the request record; Persistence across application restarts; On empty-database initialization, seed exactly eight requests: four Open including exactly one Urgent, two In progress, two Done, with every supported area represented (1 entity (Request) with migration, persistence and seed data; seed rows do not add entities: small. [be-data backend 4-8 h, small x0.6]) | G10: Factory | H10: REQ-1, REQ-2, REQ-3, REQ-6 | I10: EST-1 | J10: 0.51 | K10: 2.46
C11: List requests API | D11: 3.24 | E11: 6.48 | F11: List requests operation with optional single-status filter; Return all requests or only those matching the requested status, ordered newest first; Return the seeded request list and status counts after initialization (One optional status filter plus newest-first ordering and status counts: typical. The filter makes this larger than the closest approved small endpoint, which had no filter. [be-endpoint backend 3-6 h, verify easy x0.9]) | G11: Factory | H11: REQ-2, REQ-4, REQ-5 | I11: EST-2 | J11: 0.58 | K11: 2.77
C12: Get request by ID API | D12: 1.94 | E12: 3.89 | F12: Get-by-ID operation returns the persisted request record; Unknown ID returns a not-found response; Create response and separate get-by-ID response contain the same ID and request-field values (Plain get-by-ID read with a not-found case; no filters or joins: small, matching the approved small task. [be-endpoint backend 3-6 h, small x0.6, verify easy x0.9]) | G12: Factory | H12: REQ-1, REQ-3, REQ-4, REQ-20 | I12: EST-3 | J12: 0.35 | K12: 1.66
C13: Create request operation and validation rules | D13: 9.6 | E13: 16.8 | F13: Create request operation assigns a system-generated ID, UTC creation time, and Open status; Trim surrounding title whitespace before validating and storing; require 3 to 80 characters; Require area Kitchen, Meeting room, Open desk, Washroom, or Reception; Require priority Low, Normal, or Urgent; Allow an optional description of at most 500 characters; Invalid values return an error naming the invalid field; Keep title, area, priority, and description fixed after creation; reject attempts to change those fields or delete a request; Expose only the specified request operations; do not provide additional request operations (11 distinct rules: 3 creation assignments, 4 field validations, field-specific errors, fixed fields, no deletion, and an operation allowlist: large, matching the approved large task. [be-rules backend 8-14 h, large x1.6]) | G13: Factory | H13: REQ-4, REQ-6, REQ-7, REQ-8 | I13: EST-4 | J13: 1.57 | K13: 7.53
C14: Request status-change operation and transition rules | D14: 9.6 | E14: 16.8 | F14: Accept Open to In progress, In progress to Done, and Done to Open only; Reject all other status changes without changing the record; Unknown request ID returns not found; Missing status-change body and unrecognized status value return errors without changing the record; Do not expose edit or delete operations (8 rules: 3 allowed transitions, rejection of other transitions, unknown-ID handling, missing-body handling, unrecognized-status handling, and no edit/delete operations: typical, matching the approved typical task. [be-rules backend 8-14 h, typical]) | G14: Factory | H14: REQ-4, REQ-8, REQ-9 | I14: EST-5 | J14: 1.57 | K14: 7.53
C16: Development Total Efforts (in hours) | D16: =D9 -> 27.26 | E16: =E9 -> 49.73 | J16: =J9 -> 4.58 | K16: =K9 -> 21.95
B19: S.No | C19: Other Development Activities | D19: Minimum | E19: Maximum | F19: Comments | G19: Executor | H19: Requirement id(s) | I19: Task id | J19: API min ($) | K19: API max ($)
B20: 1 | C20: None | D20: 0 | E20: 0 | J20: 0 | K20: 0
C21: Post Development Activities Total Efforts (in hours) | D21: =SUM(D20:D20) -> 0 | E21: =SUM(E20:E20) -> 0 | J21: =SUM(J20:J20) -> 0 | K21: =SUM(K20:K20) -> 0
B24: S.No | C24: Research Task (if any) | D24: Minimum | E24: Maximum | F24: Comments | G24: Executor | H24: Requirement id(s) | I24: Task id | J24: API min ($) | K24: API max ($)
B25: 1 | C25: None | D25: 0 | E25: 0 | F25: No research task in this estimate | J25: 0 | K25: 0
C26: Research Total Efforts (in hours) | D26: =SUM(D25:D25) -> 0 | E26: =SUM(E25:E25) -> 0 | J26: =SUM(J25:J25) -> 0 | K26: =SUM(K25:K25) -> 0
B29: S.No | C29: Assumptions & Constraints
B30: 1 | C30: Spec question Q-6: Should the 1280 px table-layout target be configurable, or remain the fixed target specified for this release? → Keep 1280 px as the fixed table-layout target. (answered)
B31: 2 | C31: Spec question Q-7: Should the request detail screen add states for loading a request and for failures other than not-found? → Keep the specified detail behavior: show the request on success and “Request not found.” for an unknown ID; add no other fetch states. (answered)
B32: 3 | C32: Spec question Q-8: How should AC-1.1 verify that a newly created request can be retrieved? → Compare the create response with a separate get-by-ID API response. (answered)
B33: 4 | C33: No design was drawn for this estimate (it was left out at the start): the UI tasks are sized from the requirements alone, with no approved screens behind them, so their range is wider. A build from this estimate draws the design and has it approved before its plan.
B34: 5 | C34: Gate time, cost and duration are assumed figures, labelled cold-start until the ledger has measured runs.
B35: 6 | C35: Split before the build: EST-4, EST-5, EST-6 (agent work over 16 h or very large is split into smaller tasks; the hours stay as estimated).
B38: S.No | C38: Risks
B39: 1 | C39: Estimates will increase in case of change in requirement
B40: 2 | C40: EST-1 Request data model, migrations, persistence, and seed data: the estimators disagree, so its range is wide
B41: 3 | C41: EST-2 List requests API: the estimators disagree, so its range is wide
B42: 4 | C42: EST-3 Get request by ID API: the estimators disagree, so its range is wide
B43: 5 | C43: EST-4 Create request operation and validation rules: the estimators disagree, so its range is wide
B44: 6 | C44: EST-5 Request status-change operation and transition rules: the estimators disagree, so its range is wide

Sheet Dev Mobile Estimates
B2: Development Estimates for Maintenance Request
B3: 2026-10-10
B4: by Ahsan Raza
B5: Not in scope: no work in this estimate
C6: Grand Total (in hours) | D6: =D11+D16+D21 -> 0 | E6: =E11+E16+E21 -> 0 | F6: Sum of development, other activities and research efforts. | I6: API total ($) | J6: =J11+J16+J21 -> 0 | K6: =K11+K16+K21 -> 0
B8: S.No | C8: Task | D8: Minimum | E8: Maximum | F8: Comments | G8: Executor | H8: Requirement id(s) | I8: Task id | J8: API min ($) | K8: API max ($)
C9: None | D9: 0 | E9: 0 | J9: 0 | K9: 0
C11: Development Total Efforts (in hours) | D11: =D9 -> 0 | E11: =E9 -> 0 | J11: =J9 -> 0 | K11: =K9 -> 0
B14: S.No | C14: Other Development Activities | D14: Minimum | E14: Maximum | F14: Comments | G14: Executor | H14: Requirement id(s) | I14: Task id | J14: API min ($) | K14: API max ($)
B15: 1 | C15: None | D15: 0 | E15: 0 | J15: 0 | K15: 0
C16: Post Development Activities Total Efforts (in hours) | D16: =SUM(D15:D15) -> 0 | E16: =SUM(E15:E15) -> 0 | J16: =SUM(J15:J15) -> 0 | K16: =SUM(K15:K15) -> 0
B19: S.No | C19: Research Task (if any) | D19: Minimum | E19: Maximum | F19: Comments | G19: Executor | H19: Requirement id(s) | I19: Task id | J19: API min ($) | K19: API max ($)
B20: 1 | C20: None | D20: 0 | E20: 0 | F20: No research task in this estimate | J20: 0 | K20: 0
C21: Research Total Efforts (in hours) | D21: =SUM(D20:D20) -> 0 | E21: =SUM(E20:E20) -> 0 | J21: =SUM(J20:J20) -> 0 | K21: =SUM(K20:K20) -> 0

Sheet Dev Web Estimates
B2: Development Estimates for Maintenance Request
B3: 2026-10-10
B4: by Ahsan Raza
C6: Grand Total (in hours) | D6: =D19+D24+D29 -> 35.26 | E6: =E19+E24+E29 -> 59.28 | F6: Sum of development, other activities and research efforts. | I6: API total ($) | J6: =J19+J24+J29 -> 5.61 | K6: =K19+K24+K29 -> 26.94
B8: S.No | C8: Task | D8: Minimum | E8: Maximum | F8: Comments | G8: Executor | H8: Requirement id(s) | I8: Task id | J8: API min ($) | K8: API max ($)
B9: 1 | C9: Requests list and request creation | D9: =SUM(D10:D11) -> 14.98 | E9: =SUM(E10:E11) -> 24.96 | J9: =SUM(J10:J11) -> 2.37 | K9: =SUM(K10:K11) -> 11.38
C10: Requests list screen | D10: 9.36 | E10: 15.6 | F10: Hive Works wordmark and signed-in demo-user initials SC; Status filter choices All, Open, In progress, and Done; All selected initially; Newest-first request list, with stacked cards at 375 px and table rows at 1280 px; no horizontal page scroll at those widths; New request button; Loading state “Loading requests…”; empty state “No requests here.”; load-error state “Could not load requests.” with Retry button; Selecting a filter loads its list; returning from detail retains the selected filter and refreshes the list; After successful creation, show the new Open request at the top and select All; Created date displayed without time or timezone, in a date-only format such as “8 Oct 2026”; Status and priority badges use the specified colors and include readable text labels; Every control is keyboard reachable; text meets WCAG AA contrast (One status filter on a newest-first list, with loading/empty/error states and filter-retention behavior: typical. Responsive presentation and shared UI factors are not counted again beyond the shell. [ui-list web 6-10 h, verify hard x1.3, context partial x1.2]) | G10: Factory | H10: REQ-10, REQ-11, REQ-13, REQ-16, REQ-21, REQ-22, REQ-23 | I10: EST-7 | J10: 1.48 | K10: 7.11
C11: New request dialog | D11: 5.62 | E11: 9.36 | F11: Dialog with labeled Title, Area, Priority, and Description fields; Priority defaults to Normal; Create and Cancel controls; Show a field's validation error under that field and keep the dialog open; include the Title error “Title must be 3 to 80 characters.” for a two-character title; On non-validation create failure, show “Could not create request.”, retain entered values, and allow retry through Create; On successful creation, close the dialog and show the new Open request through the Requests list's All filter; Every field is labeled and every control is keyboard reachable (4 labeled fields with validation and submit/cancel behavior: small (up to 5 fields). Dialog error and retry states do not add fields. [ui-form web 6-10 h, small x0.6, verify hard x1.3, context partial x1.2]) | G11: Factory | H11: REQ-7, REQ-12, REQ-13, REQ-14, REQ-15, REQ-22 | I11: EST-8 | J11: 0.89 | K11: 4.27
B13: 2 | C13: Request detail and status changes | D13: =SUM(D14:D14) -> 7.8 | E13: =SUM(E14:E14) -> 12.48 | J13: =SUM(J14:J14) -> 1.2 | K13: =SUM(K14:K14) -> 5.78
C14: Request detail screen | D14: 7.8 | E14: 12.48 | F14: Back link; request title, area, priority badge, status badge, created date, and description or “No description.”; Show “Request not found.” and a link back to Requests for an unknown ID; Show Start work for Open, Mark done for In progress, and Reopen for Done; After a successful status change, show the new status badge and corresponding next action; on failure show “Could not update the request.” and retain the prior status badge; Status and priority badges use the specified colors and include readable text labels; Created date displayed without time or timezone, in a date-only format such as “8 Oct 2026”; Every control is keyboard reachable; text meets WCAG AA contrast (A detail view with one status-dependent action at a time, plus not-found and update-failure states: typical. [ui-detail web 5-8 h, verify hard x1.3, context partial x1.2]) | G14: Factory | H14: REQ-11, REQ-17, REQ-18, REQ-19, REQ-20, REQ-21, REQ-22, REQ-23 | I14: EST-9 | J14: 1.2 | K14: 5.78
B16: 3 | C16: Visual presentation and accessibility | D16: =SUM(D17:D17) -> 12.48 | E16: =SUM(E17:E17) -> 21.84 | J16: =SUM(J17:J17) -> 2.04 | K16: =SUM(K17:K17) -> 9.78
C17: Web application shell and light theme | D17: 12.48 | E17: 21.84 | F17: Browser-accessible web application shell and page layout; One light theme with sans-serif text, neutral background, and near-black text (One browser layout with an explicit light theme and shared responsive/accessibility UI factors: typical. The closest approved shell was small; this scope includes the explicit theme and shared UI factors. [ui-shell web 8-14 h, verify hard x1.3, context partial x1.2]) | G17: Factory | H17: REQ-1, REQ-21 | I17: EST-6 | J17: 2.04 | K17: 9.78
C19: Development Total Efforts (in hours) | D19: =D9+D13+D16 -> 35.26 | E19: =E9+E13+E16 -> 59.28 | J19: =J9+J13+J16 -> 5.61 | K19: =K9+K13+K16 -> 26.94
B22: S.No | C22: Other Development Activities | D22: Minimum | E22: Maximum | F22: Comments | G22: Executor | H22: Requirement id(s) | I22: Task id | J22: API min ($) | K22: API max ($)
B23: 1 | C23: None | D23: 0 | E23: 0 | J23: 0 | K23: 0
C24: Post Development Activities Total Efforts (in hours) | D24: =SUM(D23:D23) -> 0 | E24: =SUM(E23:E23) -> 0 | J24: =SUM(J23:J23) -> 0 | K24: =SUM(K23:K23) -> 0
B27: S.No | C27: Research Task (if any) | D27: Minimum | E27: Maximum | F27: Comments | G27: Executor | H27: Requirement id(s) | I27: Task id | J27: API min ($) | K27: API max ($)
B28: 1 | C28: None | D28: 0 | E28: 0 | F28: No research task in this estimate | J28: 0 | K28: 0
C29: Research Total Efforts (in hours) | D29: =SUM(D28:D28) -> 0 | E29: =SUM(E28:E28) -> 0 | J29: =SUM(J28:J28) -> 0 | K29: =SUM(K28:K28) -> 0
B32: S.No | C32: Assumptions & Constraints
B33: 1 | C33: Spec question Q-6: Should the 1280 px table-layout target be configurable, or remain the fixed target specified for this release? → Keep 1280 px as the fixed table-layout target. (answered)
B34: 2 | C34: Spec question Q-7: Should the request detail screen add states for loading a request and for failures other than not-found? → Keep the specified detail behavior: show the request on success and “Request not found.” for an unknown ID; add no other fetch states. (answered)
B35: 3 | C35: Spec question Q-8: How should AC-1.1 verify that a newly created request can be retrieved? → Compare the create response with a separate get-by-ID API response. (answered)
B36: 4 | C36: No design was drawn for this estimate (it was left out at the start): the UI tasks are sized from the requirements alone, with no approved screens behind them, so their range is wider. A build from this estimate draws the design and has it approved before its plan.
B37: 5 | C37: Gate time, cost and duration are assumed figures, labelled cold-start until the ledger has measured runs.
B38: 6 | C38: Split before the build: EST-4, EST-5, EST-6 (agent work over 16 h or very large is split into smaller tasks; the hours stay as estimated).
B41: S.No | C41: Risks
B42: 1 | C42: Estimates will increase in case of change in requirement

Sheet QA Estimates
B2: QA Estimates for Maintenance Request
B3: 2026-10-10
B4: by Ahsan Raza
C6: Grand Total Efforts (in hours) | D6: =D20 -> 13 | E6: =E20 -> 24.2 | F6: Sum of QA and Misc. | I6: API total ($) | J6: =J20 -> 1.49 | K6: =K20 -> 7.18
B8: S.No | C8: Estimation Summary | D8: Minimum | E8: Maximum | F8: Comments | G8: Executor | H8: Requirement id(s) | I8: Task id | J8: API min ($) | K8: API max ($)
B9: 1 | C9: Test Plan/Strategy | D9: 0 | E9: 0 | F9: Test planning, with the test plan, strategy and traceability matrix as outputs. Not sized in this estimate | J9: 0 | K9: 0
B10: 2 | C10: Set up of Test Environments | D10: 0 | E10: 0 | F10: Setting up code and white box test environments. Not sized in this estimate | J10: 0 | K10: 0
B11: 3 | C11: Validation and Smoke test cases | D11: =SUM(D12:D12) -> 3.6 | E11: =SUM(E12:E12) -> 7.2 | F11: Test cases to execute while debugging and white box testing | J11: =SUM(J12:J12) -> 0.64 | K11: =SUM(K12:K12) -> 3.08
C12: Automated request business-rule test cases | D12: 3.6 | E12: 7.2 | F12: Automated cases for valid creation with Open status; missing and too-short title rejection; missing area rejection; too-long description rejection; Automated cases for all three allowed status transitions and rejection of a disallowed transition; Automated cases for filtered newest-first listing and unknown-ID not-found behavior (3 test flows: creation/validation, status transitions, and filtered listing/not-found behavior: typical. [qa-cases qa 3-6 h, verify easy x0.9]) | G12: Factory | H12: REQ-24 | I12: EST-10 | J12: 0.64 | K12: 3.08
B13: 4 | C13: Validation testing | D13: =SUM(D14:D14) -> 5.4 | E13: =SUM(E14:E14) -> 9 | F13: Testing cycles; the detail is below | J13: =SUM(J14:J14) -> 0.85 | K13: =SUM(K14:K14) -> 4.1
C14: Testing Cycle 1 | D14: =D26 -> 5.4 | E14: =E26 -> 9 | J14: =J26 -> 0.85 | K14: =K26 -> 4.1
B15: 5 | C15: Smoke testing | D15: 0 | E15: 0 | F15: Smoke testing after each deployment, including preparation. Not sized in this estimate | J15: 0 | K15: 0
B16: 6 | C16: Multi Browser Compatibility testing | D16: 0 | E16: 0 | F16: Browser, OS and device compatibility. Not sized in this estimate | J16: 0 | K16: 0
B17: 7 | C17: UAT | D17: =SUM(D18:D18) -> 4 | E17: =SUM(E18:E18) -> 8 | F17: Client user acceptance testing support | J17: =SUM(J18:J18) -> 0 | K17: =SUM(K18:K18) -> 0
C18: Client acceptance testing | D18: 4 | E18: 8 | F18: Client UAT is a required human acceptance activity and does not deliver a specification requirement. (One client acceptance and regression round: typical, matching the approved typical task. [qa-uat qa 4-8 h, typical]) | G18: Human | I18: EST-12 | J18: 0 | K18: 0
B19: 8 | C19: Misc. Optional testing | D19: 0 | E19: 0 | F19: Other testing named in the breakdown, and supervisor gate time. Not sized in this estimate | J19: 0 | K19: 0
C20: Total QA Efforts | D20: =D9+D10+D11+D13+D15+D16+D17+D19 -> 13 | E20: =E9+E10+E11+E13+E15+E16+E17+E19 -> 24.2 | F20: Total hours of QA | J20: =J9+J10+J11+J13+J15+J16+J17+J19 -> 1.49 | K20: =K9+K10+K11+K13+K15+K16+K17+K19 -> 7.18
B23: S.No | C23: Validation Testing | D23: Minimum | E23: Maximum | F23: Comments | G23: Executor | H23: Requirement id(s) | I23: Task id | J23: API min ($) | K23: API max ($)
C24: Testing Cycle 1
B25: 1 | C25: Automated list-to-completion end-to-end test | D25: 5.4 | E25: 9 | F25: Run the list, create, open, Start work, Mark done, and Done-filter workflow; Verify the created request appears at the top, then appears in the Done-filtered list after completion (One multi-step list-to-completion workflow spanning list, create, detail, status changes and the Done filter; broader than a short flow: typical, matching the approved typical task. [qa-e2e qa 6-10 h, verify easy x0.9]) | G25: Factory | H25: REQ-24 | I25: EST-11 | J25: 0.85 | K25: 4.1
C26: Total Testing Cycle 1 | D26: =D25 -> 5.4 | E26: =E25 -> 9 | F26: Sum of testing cycle 1 | J26: =J25 -> 0.85 | K26: =K25 -> 4.1
B29: S.No | C29: Assumptions & Constraints
B30: 1 | C30: Spec question Q-6: Should the 1280 px table-layout target be configurable, or remain the fixed target specified for this release? → Keep 1280 px as the fixed table-layout target. (answered)
B31: 2 | C31: Spec question Q-7: Should the request detail screen add states for loading a request and for failures other than not-found? → Keep the specified detail behavior: show the request on success and “Request not found.” for an unknown ID; add no other fetch states. (answered)
B32: 3 | C32: Spec question Q-8: How should AC-1.1 verify that a newly created request can be retrieved? → Compare the create response with a separate get-by-ID API response. (answered)
B33: 4 | C33: No design was drawn for this estimate (it was left out at the start): the UI tasks are sized from the requirements alone, with no approved screens behind them, so their range is wider. A build from this estimate draws the design and has it approved before its plan.
B34: 5 | C34: Gate time, cost and duration are assumed figures, labelled cold-start until the ledger has measured runs.
B35: 6 | C35: Split before the build: EST-4, EST-5, EST-6 (agent work over 16 h or very large is split into smaller tasks; the hours stay as estimated).
B38: S.No | C38: Risks
B39: 1 | C39: Estimates will increase in case of change in requirement
B40: 2 | C40: EST-10 Automated request business-rule test cases: the estimators disagree, so its range is wide
B41: 3 | C41: EST-11 Automated list-to-completion end-to-end test: the estimators disagree, so its range is wide

Sheet Design Estimates
B2: Design Estimates for Maintenance Request
B3: 2026-10-10
B4: by Ahsan Raza
B5: Not in scope: no work in this estimate
C6: Grand Total (in hours) | D6: =D11+D16+D21 -> 0 | E6: =E11+E16+E21 -> 0 | F6: Sum of development, other activities and research efforts. | I6: API total ($) | J6: =J11+J16+J21 -> 0 | K6: =K11+K16+K21 -> 0
B8: S.No | C8: Task | D8: Minimum | E8: Maximum | F8: Comments | G8: Executor | H8: Requirement id(s) | I8: Task id | J8: API min ($) | K8: API max ($)
C9: None | D9: 0 | E9: 0 | J9: 0 | K9: 0
C11: Development Total Efforts (in hours) | D11: =D9 -> 0 | E11: =E9 -> 0 | J11: =J9 -> 0 | K11: =K9 -> 0
B14: S.No | C14: Other Development Activities | D14: Minimum | E14: Maximum | F14: Comments | G14: Executor | H14: Requirement id(s) | I14: Task id | J14: API min ($) | K14: API max ($)
B15: 1 | C15: None | D15: 0 | E15: 0 | J15: 0 | K15: 0
C16: Post Development Activities Total Efforts (in hours) | D16: =SUM(D15:D15) -> 0 | E16: =SUM(E15:E15) -> 0 | J16: =SUM(J15:J15) -> 0 | K16: =SUM(K15:K15) -> 0
B19: S.No | C19: Research Task (if any) | D19: Minimum | E19: Maximum | F19: Comments | G19: Executor | H19: Requirement id(s) | I19: Task id | J19: API min ($) | K19: API max ($)
B20: 1 | C20: None | D20: 0 | E20: 0 | F20: No research task in this estimate | J20: 0 | K20: 0
C21: Research Total Efforts (in hours) | D21: =SUM(D20:D20) -> 0 | E21: =SUM(E20:E20) -> 0 | J21: =SUM(J20:J20) -> 0 | K21: =SUM(K20:K20) -> 0

Sheet Other Estimates
B2: Other Estimates for Maintenance Request
B3: 2026-10-10
B4: by Ahsan Raza
B6: GD
B7: Not in scope: no work in this estimate
B8: S.No | C8: Task | D8: Minimum | E8: Maximum | F8: Comments | G8: Executor | H8: Requirement id(s) | I8: Task id | J8: API min ($) | K8: API max ($)
B9: 1 | C9: None | D9: 0 | E9: 0 | J9: 0 | K9: 0
C10: GD TOTAL | D10: =SUM(D9:D9) -> 0 | E10: =SUM(E9:E9) -> 0 | J10: =SUM(J9:J9) -> 0 | K10: =SUM(K9:K9) -> 0
B13: PM
B14: S.No | C14: Task | D14: Minimum | E14: Maximum | F14: Comments | G14: Executor | H14: Requirement id(s) | I14: Task id | J14: API min ($) | K14: API max ($)
B15: 1 | C15: Client liaison and project management | D15: 4 | E15: 8 | F15: Required human client liaison and project-management overhead; factory planning and coordination of its own work are excluded. (Client liaison, scope decisions and sign-offs across the project; assuming about a month of delivery: typical, matching the approved typical task. [pm-management pm 4-8 h, typical]) | G15: Human | I15: EST-13 | J15: 0 | K15: 0
C16: PM TOTAL | D16: =SUM(D15:D15) -> 4 | E16: =SUM(E15:E15) -> 8 | J16: =SUM(J15:J15) -> 0 | K16: =SUM(K15:K15) -> 0
B19: PDM
B20: Not in scope: no work in this estimate
B21: S.No | C21: Task | D21: Minimum | E21: Maximum | F21: Comments | G21: Executor | H21: Requirement id(s) | I21: Task id | J21: API min ($) | K21: API max ($)
B22: 1 | C22: None | D22: 0 | E22: 0 | J22: 0 | K22: 0
C23: PDM TOTAL | D23: =SUM(D22:D22) -> 0 | E23: =SUM(E22:E22) -> 0 | J23: =SUM(J22:J22) -> 0 | K23: =SUM(K22:K22) -> 0
B26: Cross-cutting
B27: S.No | C27: Task | D27: Minimum | E27: Maximum | F27: Comments | G27: Executor | H27: Requirement id(s) | I27: Task id | J27: API min ($) | K27: API max ($)
B28: 1 | C28: None | D28: 0 | E28: 0 | J28: 0 | K28: 0
C29: Cross-cutting TOTAL | D29: =SUM(D28:D28) -> 0 | E29: =SUM(E28:E28) -> 0 | J29: =SUM(J28:J28) -> 0 | K29: =SUM(K28:K28) -> 0

Sheet All Tasks
B1: All tasks: Maintenance Request
B2: Filter or sort any column. The Total row adds up only the rows the filter shows.
B4: Task id | C4: Task | D4: Track | E4: Module | F4: Executor | G4: Requirement id(s) | H4: Minimum | I4: Maximum | J4: API min ($) | K4: API max ($)
B5: EST-1 | C5: Request data model, migrations, persistence, and seed data | D5: Backend | E5: Request data and HTTP API | F5: Factory | G5: REQ-1, REQ-2, REQ-3, REQ-6 | H5: 2.88 | I5: 5.76 | J5: 0.51 | K5: 2.46
B6: EST-2 | C6: List requests API | D6: Backend | E6: Request data and HTTP API | F6: Factory | G6: REQ-2, REQ-4, REQ-5 | H6: 3.24 | I6: 6.48 | J6: 0.58 | K6: 2.77
B7: EST-3 | C7: Get request by ID API | D7: Backend | E7: Request data and HTTP API | F7: Factory | G7: REQ-1, REQ-3, REQ-4, REQ-20 | H7: 1.94 | I7: 3.89 | J7: 0.35 | K7: 1.66
B8: EST-4 | C8: Create request operation and validation rules | D8: Backend | E8: Request data and HTTP API | F8: Factory | G8: REQ-4, REQ-6, REQ-7, REQ-8 | H8: 9.6 | I8: 16.8 | J8: 1.57 | K8: 7.53
B9: EST-5 | C9: Request status-change operation and transition rules | D9: Backend | E9: Request data and HTTP API | F9: Factory | G9: REQ-4, REQ-8, REQ-9 | H9: 9.6 | I9: 16.8 | J9: 1.57 | K9: 7.53
B10: EST-6 | C10: Web application shell and light theme | D10: Web | E10: Visual presentation and accessibility | F10: Factory | G10: REQ-1, REQ-21 | H10: 12.48 | I10: 21.84 | J10: 2.04 | K10: 9.78
B11: EST-7 | C11: Requests list screen | D11: Web | E11: Requests list and request creation | F11: Factory | G11: REQ-10, REQ-11, REQ-13, REQ-16, REQ-21, REQ-22, REQ-23 | H11: 9.36 | I11: 15.6 | J11: 1.48 | K11: 7.11
B12: EST-8 | C12: New request dialog | D12: Web | E12: Requests list and request creation | F12: Factory | G12: REQ-7, REQ-12, REQ-13, REQ-14, REQ-15, REQ-22 | H12: 5.62 | I12: 9.36 | J12: 0.89 | K12: 4.27
B13: EST-9 | C13: Request detail screen | D13: Web | E13: Request detail and status changes | F13: Factory | G13: REQ-11, REQ-17, REQ-18, REQ-19, REQ-20, REQ-21, REQ-22, REQ-23 | H13: 7.8 | I13: 12.48 | J13: 1.2 | K13: 5.78
B14: EST-10 | C14: Automated request business-rule test cases | D14: QA | E14: Automated verification | F14: Factory | G14: REQ-24 | H14: 3.6 | I14: 7.2 | J14: 0.64 | K14: 3.08
B15: EST-11 | C15: Automated list-to-completion end-to-end test | D15: QA | E15: Automated verification | F15: Factory | G15: REQ-24 | H15: 5.4 | I15: 9 | J15: 0.85 | K15: 4.1
B16: EST-12 | C16: Client acceptance testing | D16: QA | E16: Automated verification | F16: Human | H16: 4 | I16: 8 | J16: 0 | K16: 0
B17: EST-13 | C17: Client liaison and project management | D17: PM | E17: Automated verification | F17: Human | H17: 4 | I17: 8 | J17: 0 | K17: 0
C18: Total (rows shown) | H18: =SUBTOTAL(9,H5:H17) -> 79.52 | I18: =SUBTOTAL(9,I5:I17) -> 141.21 | J18: =SUBTOTAL(9,J5:J17) -> 11.68 | K18: =SUBTOTAL(9,K5:K17) -> 56.07

Sheet Confidence
B2: Delivery model | C2: agentic
B3: Size band | C3: M
B4: Uncertainty | C4: high
B5: Cost confidence | C5: partial
B6: Benchmark records | C6: 21
B7: Flagged tasks (estimators disagree) | C7: 7
B8: Spec sha | C8: e2059a0dfaf708960598d4f8255b9841bd06bd97f1f8a91187b28850ce6a85d2
B9: Breakdown sha | C9: 9f6a33e8048b820d68f3887c921710cdce802e8b48d6503e0d4781362d0669c7
B10: Task catalogue | C10: 2026-10-06.1 (stack dotnet)
B11: Catalogue status | C11: reference hours, not yet measured
B12: Factory hours basis | C12: cold-start: each task's sized hours, a reference size, until this factory has built enough tasks of its class (3 or more)
B14: API cost by phase | C14: Based on | D14: Ledger runs | E14: Eval runs
B15: planning ($0.51-7.07) | C15: measured: p10-p90 of 8 runs (8 ledger) | D15: 8 | E15: 0
B16: breakdown-estimate ($0.47-0.95) | C16: measured: p10-p90 of 3 runs (3 ledger) | D16: 3 | E16: 0
B17: build ($11.62-54.33) | C17: measured: p10-p90 of 6 runs (3 ledger, 3 eval) | D17: 3 | E17: 3
B18: verification ($0.06-1.74) | C18: measured: p10-p90 of 4 runs (2 ledger, 2 eval) | D18: 2 | E18: 2

Sheet Anchors
B1: Anchors
B2: Task | C2: Title | D2: Min (h) | E2: Max (h) | F2: Why a fair reference
B3: EST-1 | C3: Request data model, migrations, persistence, and seed data | D3: 2.88 | E3: 5.76 | F3: 1 entity (Request) with migration, persistence and seed data; seed rows do not add entities: small. [be-data backend 4-8 h, small x0.6] (Median of the estimators; the lead estimator read 2.4-4.8 h, and the ratios multiply that reading.)
B4: EST-2 | C4: List requests API | D4: 3.24 | E4: 6.48 | F4: One optional status filter plus newest-first ordering and status counts: typical. The filter makes this larger than the closest approved small endpoint, which had no filter. [be-endpoint backend 3-6 h, verify easy x0.9] (Median of the estimators; the lead estimator read 2.7-5.4 h, and the ratios multiply that reading.)
B5: EST-4 | C5: Create request operation and validation rules | D5: 9.6 | E5: 16.8 | F5: 11 distinct rules: 3 creation assignments, 4 field validations, field-specific errors, fixed fields, no deletion, and an operation allowlist: large, matching the approved large task. [be-rules backend 8-14 h, large x1.6] (Median of the estimators; the lead estimator read 12.8-22.4 h, and the ratios multiply that reading.)
B6: EST-6 | C6: Web application shell and light theme | D6: 12.48 | E6: 21.84 | F6: One browser layout with an explicit light theme and shared responsive/accessibility UI factors: typical. The closest approved shell was small; this scope includes the explicit theme and shared UI factors. [ui-shell web 8-14 h, verify hard x1.3, context partial x1.2]
B7: EST-7 | C7: Requests list screen | D7: 9.36 | E7: 15.6 | F7: One status filter on a newest-first list, with loading/empty/error states and filter-retention behavior: typical. Responsive presentation and shared UI factors are not counted again beyond the shell. [ui-list web 6-10 h, verify hard x1.3, context partial x1.2]
B8: EST-8 | C8: New request dialog | D8: 5.62 | E8: 9.36 | F8: 4 labeled fields with validation and submit/cancel behavior: small (up to 5 fields). Dialog error and retry states do not add fields. [ui-form web 6-10 h, small x0.6, verify hard x1.3, context partial x1.2]
B9: EST-9 | C9: Request detail screen | D9: 7.8 | E9: 12.48 | F9: A detail view with one status-dependent action at a time, plus not-found and update-failure states: typical. [ui-detail web 5-8 h, verify hard x1.3, context partial x1.2]
B10: EST-10 | C10: Automated request business-rule test cases | D10: 3.6 | E10: 7.2 | F10: 3 test flows: creation/validation, status transitions, and filtered listing/not-found behavior: typical. [qa-cases qa 3-6 h, verify easy x0.9] (Median of the estimators; the lead estimator read 2.7-5.4 h, and the ratios multiply that reading.)
B11: EST-11 | C11: Automated list-to-completion end-to-end test | D11: 5.4 | E11: 9 | F11: One multi-step list-to-completion workflow spanning list, create, detail, status changes and the Done filter; broader than a short flow: typical, matching the approved typical task. [qa-e2e qa 6-10 h, verify easy x0.9]
B12: EST-12 | C12: Client acceptance testing | D12: 4 | E12: 8 | F12: One client acceptance and regression round: typical, matching the approved typical task. [qa-uat qa 4-8 h, typical]
B13: EST-13 | C13: Client liaison and project management | D13: 4 | E13: 8 | F13: Client liaison, scope decisions and sign-offs across the project; assuming about a month of delivery: typical, matching the approved typical task. [pm-management pm 4-8 h, typical]
B16: Task | C16: Title | D16: Anchor | E16: Ratio | F16: Reason | G16: Min (h) | H16: Max (h) | I16: Executor | J16: Flagged
B17: EST-1 | C17: Request data model, migrations, persistence, and seed data | D17: EST-1 | E17: 1 | F17: 1 entity (Request) with migration, persistence and seed data; seed rows do not add entities: small. [be-data backend 4-8 h, small x0.6] | G17: 2.88 | H17: 5.76 | I17: factory | J17: yes
B18: EST-2 | C18: List requests API | D18: EST-2 | E18: 1 | F18: One optional status filter plus newest-first ordering and status counts: typical. The filter makes this larger than the closest approved small endpoint, which had no filter. [be-endpoint backend 3-6 h, verify easy x0.9] | G18: 3.24 | H18: 6.48 | I18: factory | J18: yes
B19: EST-3 | C19: Get request by ID API | D19: EST-2 | E19: 0.6 | F19: Plain get-by-ID read with a not-found case; no filters or joins: small, matching the approved small task. [be-endpoint backend 3-6 h, small x0.6, verify easy x0.9] | G19: 1.94 | H19: 3.89 | I19: factory | J19: yes
B20: EST-4 | C20: Create request operation and validation rules | D20: EST-4 | E20: 1 | F20: 11 distinct rules: 3 creation assignments, 4 field validations, field-specific errors, fixed fields, no deletion, and an operation allowlist: large, matching the approved large task. [be-rules backend 8-14 h, large x1.6] | G20: 9.6 | H20: 16.8 | I20: factory | J20: yes
B21: EST-5 | C21: Request status-change operation and transition rules | D21: EST-4 | E21: 0.625 | F21: 8 rules: 3 allowed transitions, rejection of other transitions, unknown-ID handling, missing-body handling, unrecognized-status handling, and no edit/delete operations: typical, matching the approved typical task. [be-rules backend 8-14 h, typical] | G21: 9.6 | H21: 16.8 | I21: factory | J21: yes
B22: EST-6 | C22: Web application shell and light theme | D22: EST-6 | E22: 1 | F22: One browser layout with an explicit light theme and shared responsive/accessibility UI factors: typical. The closest approved shell was small; this scope includes the explicit theme and shared UI factors. [ui-shell web 8-14 h, verify hard x1.3, context partial x1.2] | G22: 12.48 | H22: 21.84 | I22: factory
B23: EST-7 | C23: Requests list screen | D23: EST-7 | E23: 1 | F23: One status filter on a newest-first list, with loading/empty/error states and filter-retention behavior: typical. Responsive presentation and shared UI factors are not counted again beyond the shell. [ui-list web 6-10 h, verify hard x1.3, context partial x1.2] | G23: 9.36 | H23: 15.6 | I23: factory
B24: EST-8 | C24: New request dialog | D24: EST-8 | E24: 1 | F24: 4 labeled fields with validation and submit/cancel behavior: small (up to 5 fields). Dialog error and retry states do not add fields. [ui-form web 6-10 h, small x0.6, verify hard x1.3, context partial x1.2] | G24: 5.62 | H24: 9.36 | I24: factory
B25: EST-9 | C25: Request detail screen | D25: EST-9 | E25: 1 | F25: A detail view with one status-dependent action at a time, plus not-found and update-failure states: typical. [ui-detail web 5-8 h, verify hard x1.3, context partial x1.2] | G25: 7.8 | H25: 12.48 | I25: factory
B26: EST-10 | C26: Automated request business-rule test cases | D26: EST-10 | E26: 1 | F26: 3 test flows: creation/validation, status transitions, and filtered listing/not-found behavior: typical. [qa-cases qa 3-6 h, verify easy x0.9] | G26: 3.6 | H26: 7.2 | I26: factory | J26: yes
B27: EST-11 | C27: Automated list-to-completion end-to-end test | D27: EST-11 | E27: 1 | F27: One multi-step list-to-completion workflow spanning list, create, detail, status changes and the Done filter; broader than a short flow: typical, matching the approved typical task. [qa-e2e qa 6-10 h, verify easy x0.9] | G27: 5.4 | H27: 9 | I27: factory | J27: yes
B28: EST-12 | C28: Client acceptance testing | D28: EST-12 | E28: 1 | F28: One client acceptance and regression round: typical, matching the approved typical task. [qa-uat qa 4-8 h, typical] | G28: 4 | H28: 8 | I28: human
B29: EST-13 | C29: Client liaison and project management | D29: EST-13 | E29: 1 | F29: Client liaison, scope decisions and sign-offs across the project; assuming about a month of delivery: typical, matching the approved typical task. [pm-management pm 4-8 h, typical] | G29: 4 | H29: 8 | I29: human

Sheet Traceability
B1: Requirements and traceability
B2: Requirement | C2: Title | D2: Tasks
B3: REQ-1 | C3: The maintenance request system shall provide a browser-accessible web front end, an HTTP API, and a database that stores request records. | D3: EST-1, EST-3, EST-6
B4: REQ-10 | C4: The Requests screen shall display the Hive Works wordmark, the signed-in demo user's initials SC, a status filter with All, Open, In prog... | D4: EST-7
B5: REQ-11 | C5: When a user selects a status filter or returns from request detail, the Requests screen shall load the list for the selected filter and r... | D5: EST-7, EST-9
B6: REQ-12 | C6: When the user opens New request, the Requests screen shall show a dialog with Title, Area, Priority defaulting to Normal, and Description... | D6: EST-8
B7: REQ-13 | C7: When valid request creation succeeds, the Requests screen shall close the dialog, select All, and show the new Open request at the top of... | D7: EST-7, EST-8
B8: REQ-14 | C8: When a create field fails validation, the Requests screen shall keep the dialog open and display the field's error message under that field. | D8: EST-8
B9: REQ-15 | C9: When the create API call fails for a reason other than field validation, the Requests screen shall show “Could not create request.” in th... | D9: EST-8
B10: REQ-16 | C10: While requests are loading, absent for the selected filter, or fail to load, the Requests screen shall display the corresponding loading,... | D10: EST-7
B11: REQ-17 | C11: When a request exists, the request detail screen shall display a back link, its title, area, priority badge, status badge, created date, ... | D11: EST-9
B12: REQ-18 | C12: The request detail screen shall show Start work for Open, Mark done for In progress, and Reopen for Done. | D12: EST-9
B13: REQ-19 | C13: When a status change succeeds or fails, the request detail screen shall show the new status and corresponding action only after success, ... | D13: EST-9
... B26: REQ-9 | C26: The maintenance request API shall accept only Open to In progress, In progress to Done, and Done to Open status transitions, reject all o... | D26: EST-5
B29: Tasks with no requirement (named overheads)
B30: EST-12 | C30: Client acceptance testing | D30: Client UAT is a required human acceptance activity and does not deliver a specification requirement.
B31: EST-13 | C31: Client liaison and project management | D31: Required human client liaison and project-management overhead; factory planning and coordination of its own work are excluded.

Sheet Parameters
B1: Assumed parameters and gate time (all editable, all assumed)
B2: Parameter | C2: Min | D2: Max
B3: Clarify minutes per question | C3: 2 | D3: 5
B4: Approval minutes per section | C4: 3 | D4: 8
B5: PR review minutes, low risk | C5: 10 | D5: 20
B6: PR review minutes, medium risk | C6: 20 | D6: 40
B7: PR review minutes, high risk | C7: 40 | D7: 90
B8: Parked-run rate | C8: 0.05 | D8: 0.15
B9: Parked-run intervention minutes | C9: 20 | D9: 60
B10: Waiver minutes | C10: 5 | D10: 15
B11: Cold-start dollars per task | C11: 1.3 | D11: 1.8
B12: Estimator tolerance | C12: 0.5
B13: Tasks per PR | C13: 2
B14: Hours per day | C14: 8
B15: Hours per week | C15: 40
B16: Agentic build factor | C16: 1.25
B19: Gate hours in this estimate
B20: None: the solely agentic model has no supervisor gates
B22: No rates were given, so there is no cost overlay.

Sheet Gates
B1: Estimate gates and waivers
B2: Gate | C2: Result | D2: Details
B3: estimate.e1-readiness | C3: passed | D3: 24 requirements, lint, critic and round trip clean (3 problems settled by questions), no open questions
B4: estimate.e2-req-to-task | C4: passed | D4: all 24 requirements have a task
B5: estimate.e3-task-to-req | C5: passed | D5: every task cites a requirement or a named overhead
B6: estimate.e2c-task-kind | C6: passed | D6: every task has a catalogue kind that fits its track (catalogue 2026-10-06.1)
B7: estimate.e4-checklist | C7: passed | D7: 14 checklist items each in, or out with a reason
B8: estimate.e1c-design-coverage | C8: passed | D8: no approved screens, and no task cites one
B9: estimate.e5-consistency | C9: passed | D9: similar tasks are within tolerance
B10: estimate.e6-lint | C10: passed | D10: totals, ratios and costs recompute cleanly
B11: estimate.e7-approval | C11: passed | D11: approved by mhamza
B14: Waivers
B15: Gates | C15: Step | D15: Waived by and why
B16: None
