Workbook

Sheet Summary
B1: Folio3 Project Estimation
B2: Parts Quick Order
B3: Summary of Estimates
B5: Client Name | C5: Demo Garage
B6: Project Manager | C6: mhamza
B7: Date | C7: 2026-10-05
B8: Version | C8: 1
C9: Human effort (in hours) | F9: Agent (in hours)
B10: Task Summary | C10: Human min (h) | D10: Human max (h) | E10: Comments | F10: Agent min (h) | G10: Agent max (h) | H10: Avg | I10: Resources | J10: Weeks
B11: Backend Development Estimates | C11: ='Dev Backend Estimates'!D6 -> 30.57 | D11: ='Dev Backend Estimates'!E6 -> 51.55 | E11: Grand total of the Backend sheet | F11: ='Dev Backend Estimates'!J6 -> 62.58 | G11: ='Dev Backend Estimates'!K6 -> 110.56 | H11: =ROUND((C11+D11)/2,2) -> 41.06 | I11: 1 | J11: =ROUND(H11/($C$48*I11),2) -> 1.03
B12: Mobile Development Estimates | C12: ='Dev Mobile Estimates'!D6 -> 0 | D12: ='Dev Mobile Estimates'!E6 -> 0 | E12: Grand total of the Mobile sheet | F12: ='Dev Mobile Estimates'!J6 -> 0 | G12: ='Dev Mobile Estimates'!K6 -> 0 | H12: =ROUND((C12+D12)/2,2) -> 0 | I12: 1 | J12: =ROUND(H12/($C$48*I12),2) -> 0
B13: Admin Development Estimates | C13: ='Dev Web Estimates'!D6 -> 6.55 | D13: ='Dev Web Estimates'!E6 -> 13.1 | E13: Grand total of the Web / Admin sheet | F13: ='Dev Web Estimates'!J6 -> 65.37 | G13: ='Dev Web Estimates'!K6 -> 109.28 | H13: =ROUND((C13+D13)/2,2) -> 9.82 | I13: 1 | J13: =ROUND(H13/($C$48*I13),2) -> 0.25
B14: QA Estimates | C14: ='QA Estimates'!D6 -> 4 | D14: ='QA Estimates'!E6 -> 8 | E14: Grand total of the QA sheet | F14: ='QA Estimates'!J6 -> 18.9 | G14: ='QA Estimates'!K6 -> 35.8 | H14: =ROUND((C14+D14)/2,2) -> 6 | I14: 1 | J14: =ROUND(H14/($C$48*I14),2) -> 0.15
B15: GD Estimates | C15: ='Other Estimates'!D10 -> 0 | D15: ='Other Estimates'!E10 -> 0 | E15: Other Estimates sheet | F15: ='Other Estimates'!J10 -> 0 | G15: ='Other Estimates'!K10 -> 0 | H15: =ROUND((C15+D15)/2,2) -> 0 | I15: 1 | J15: =ROUND(H15/($C$48*I15),2) -> 0
B16: PM Estimates | C16: ='Other Estimates'!D16 -> 4 | D16: ='Other Estimates'!E16 -> 8 | E16: Other Estimates sheet | F16: ='Other Estimates'!J16 -> 0 | G16: ='Other Estimates'!K16 -> 0 | H16: =ROUND((C16+D16)/2,2) -> 6 | I16: 1 | J16: =ROUND(H16/($C$48*I16),2) -> 0.15
B17: PDM Estimates | C17: ='Other Estimates'!D22 -> 0 | D17: ='Other Estimates'!E22 -> 0 | E17: Other Estimates sheet | F17: ='Other Estimates'!J22 -> 2.88 | G17: ='Other Estimates'!K22 -> 5.76 | H17: =ROUND((C17+D17)/2,2) -> 0 | I17: 1 | J17: =ROUND(H17/($C$48*I17),2) -> 0
B18: Cross-cutting Estimates | C18: ='Other Estimates'!D28 -> 0 | D18: ='Other Estimates'!E28 -> 0 | E18: Other Estimates sheet: deployment, documentation and the like | F18: ='Other Estimates'!J28 -> 0 | G18: ='Other Estimates'!K28 -> 0 | H18: =ROUND((C18+D18)/2,2) -> 0 | I18: 1 | J18: =ROUND(H18/($C$48*I18),2) -> 0
B19: Design Estimates | C19: ='Design Estimates'!D6 -> 2 | D19: ='Design Estimates'!E6 -> 4 | E19: Counted in the total only when Design is switched on below | F19: ='Design Estimates'!J6 -> 0 | G19: ='Design Estimates'!K6 -> 0 | H19: =ROUND((C19+D19)/2,2) -> 3 | I19: 1 | J19: =ROUND(H19/($C$48*I19),2) -> 0.08
B20: Total | C20: =SUM(C11:C18)+IF($C$47="Yes",C19,0) -> 47.12 | D20: =SUM(D11:D18)+IF($C$47="Yes",D19,0) -> 84.65 | F20: =SUM(F11:F18)+IF($C$47="Yes",F19,0) -> 149.73 | G20: =SUM(G11:G18)+IF($C$47="Yes",G19,0) -> 261.4 | H20: =ROUND((C20+D20)/2,2) -> 65.89
B23: List of Special Considerations, where applicable:
B24: Tasks | C24: Action | E24: Comments
B25: Application type (mobile, desktop, web) | C25: Backend + Web | E25: From the tracks that have work
B26: Platforms/OS supported | C26: Not specified | E26: Confirm with the client
B27: Browsers supported | C27: Assumed: The latest two versions of Chrome, Edge, Safari and Firefox. | E27: Factory assumption ASM-17, confirm with the client
B28: Deployment (cloud, dedicated server, enterprise internal network) | C28: Not specified | E28: Confirm with the client
B29: Performance, Load requirements | C29: Assumed: Up to 1,000 users and 100,000 records in the first year. | E29: Factory assumption ASM-16, confirm with the client
B30: Security requirements | C30: Not specified | E30: Confirm with the client
B31: Documentation requirements | C31: Not specified | E31: Confirm with the client
B32: Other custom? | C32: No
B46: Parameters
B47: Include Design in total | C47: Yes
B48: Hours per week | C48: 40
B49: Feedback rounds | C49: 2
B50: Stack chosen by | C50: client
B51: Delivery model | C51: Solely agentic
B55: API credit cost (USD)
B56: Phase | C56: Min ($) | D56: Max ($) | E56: Based on
B57: planning | C57: 0.74 | D57: 2.86 | E57: measured: p10-p90 of 4 runs
B58: design | C58: 0.06 | D58: 7.98 | E58: measured: p10-p90 of 4 runs
B59: breakdown-estimate | C59: 0.8 | D59: 0.8 | E59: measured: p10-p90 of 1 run
...

Sheet Dev Backend Estimates
B2: Development Estimates for Parts Quick Order
B3: 2026-10-05
B4: by mhamza
C6: Grand Total (in hours) | D6: =D26+D31+D36 -> 30.57 | E6: =E26+E31+E36 -> 51.55 | F6: Sum of development, other activities and research efforts. | I6: Agent total (h) | J6: =J26+J31+J36 -> 62.58 | K6: =K26+K31+K36 -> 110.56
B8: S.No | C8: Task | D8: Human min (h) | E8: Human max (h) | F8: Comments | G8: Executor | H8: Requirement id(s) | I8: Task id | J8: Agent min (h) | K8: Agent max (h) | L8: API min ($) | M8: API max ($)
B9: 1 | C9: Portal shell, navigation and cross-cutting | D9: =SUM(D10:D10) -> 17.47 | E9: =SUM(E10:E10) -> 30.58 | J9: =SUM(J10:J10) -> 17.47 | K9: =SUM(K10:K10) -> 30.58 | L9: =SUM(L10:L10) -> 1.99 | M9: =SUM(M10:M10) -> 6.7
C10: Environments, CI/CD and hosting for API and portal | D10: 17.47 | E10: 30.58 | F10: Environment setup delivers no requirement on its own | G10: Joint | I10: EST-1 | J10: 17.47 | K10: 30.58 | L10: 1.99 | M10: 6.7
B12: 2 | C12: Find parts | D12: =SUM(D13:D14) -> 0 | E12: =SUM(E13:E14) -> 0 | J12: =SUM(J13:J14) -> 5.52 | K12: =SUM(K13:K14) -> 11.04 | L12: =SUM(L13:L14) -> 0.69 | M12: =SUM(M13:M14) -> 2.31
C13: GET /api/parts: search, filters, paging, stock state | D13: 0 | E13: 0 | F13: Sorted by name A–Z, 20 per page, total count; Fields image (or null), name, partNumber, brand, price in GBP with 2 decimals, stockState, stock (whole number); Stock state: In stock (≥5), Low stock (n left) (1–4), Out of stock (0); Search q of at least 2 characters, case-insensitive, on name or part number; 1 character applies no filter; One category and one brand filter combined with search; All means no filter; Empty result returns 200 with empty list and total 0; p95 under 500 ms with 5,000 parts | G13: Factory | H13: REQ-2, REQ-3, REQ-4, REQ-5, REQ-38 | I13: EST-4 | J13: 3.9 | K13: 7.8 | L13: 0.49 | M13: 1.63
C14: GET /api/parts/brands | D14: 0 | E14: 0 | F14: Distinct brand list taken from the parts data | G14: Factory | H14: REQ-5 | I14: EST-5 | J14: 1.62 | K14: 3.24 | L14: 0.2 | M14: 0.68
B16: 3 | C16: Placing orders (orders API) | D16: =SUM(D17:D18) -> 0 | E16: =SUM(E17:E18) -> 0 | J16: =SUM(J17:J18) -> 14.96 | K16: =SUM(K17:K18) -> 26.72 | L16: =SUM(L17:L18) -> 1.73 | M16: =SUM(M17:M18) -> 5.81
C17: Orders data model, migrations and seed data | D17: 0 | E17: 0 | F17: orders table: buyer ID, order number, date placed, delivery address, delivery option (STANDARD/NEXT_DAY), total, status; order_lines table: order, part number (refers to existing parts), quantity, unit price; Status values Placed, Packed, Dispatched, Delivered, Cancelled; Database sequence for ORD- + 6 zero-padded digits (ORD-000001); Indexes on buyer and date placed for 100,000 order records (NFR-2); Parts table stays read-only; Seed of 5,000 parts for the load test | G17: Factory | H17: REQ-20, REQ-28, REQ-30, REQ-38 | I17: EST-2 | J17: 2.16 | K17: 4.32 | L17: 0.27 | M17: 0.9
C18: POST /api/orders: place order rules | D18: 0 | E18: 0 | F18: Validation 400 with error field: no lines, quantity outside 1–99, unknown part number, address outside 5–200 characters, missing or unknown delivery option; Stock re-check: 409 listing each affected part number with available stock, no order saved; Unit price from current part price; client-sent price ignored; Total = subtotal + delivery charge (Standard £0.00, Next day £9.99); Status Placed and sequential order number ORD-000001; 201 response with orderNumber, status and total; Stock quantity in parts database left unchanged | G18: Factory | H18: REQ-20, REQ-21, REQ-22, REQ-25 | I18: EST-6 | J18: 12.8 | K18: 22.4 | L18: 1.46 | M18: 4.91
B20: 4 | C20: My orders | D20: =SUM(D21:D24) -> 13.1 | E20: =SUM(E21:E24) -> 20.97 | J20: =SUM(J21:J24) -> 24.63 | K20: =SUM(K21:K24) -> 42.22 | L20: =SUM(L21:L24) -> 2.77 | M20: =SUM(M21:M24) -> 9.32
C21: Buyer identity from existing company login session | D21: 13.1 | E21: 20.97 | F21: Validate existing company login session token or cookie on every API request (ASM-5); Read buyer ID from session for order ownership; Expose signed-in buyer ID to the portal for the cart storage key | G21: Joint | H21: REQ-27, REQ-16 | I21: EST-3 | J21: 13.1 | K21: 20.97 | L21: 1.41 | M21: 4.75
C22: GET /api/orders: buyer's orders list with status filter | D22: 0 | E22: 0 | F22: Only the signed-in buyer's orders; Newest first; Fields order number, datePlaced, itemCount (total of quantities), total, status; status query filter; Empty list with 200 when no orders | G22: Factory | H22: REQ-27, REQ-28, REQ-29, REQ-35 | I22: EST-7 | J22: 2.7 | K22: 5.4 | L22: 0.34 | M22: 1.13
C23: GET /api/orders/{orderNumber}: order detail | D23: 0 | E23: 0 | F23: Lines with part number, name, quantity, unit price; Delivery address, delivery option, total, status; 404 for another buyer's order | G23: Factory | H23: REQ-27, REQ-30 | I23: EST-8 | J23: 1.62 | K23: 3.24 | L23: 0.2 | M23: 0.68
C24: POST /api/orders/{orderNumber}/cancel: cancel rules | D24: 0 | E24: 0 | F24: Cancel only if status is still Placed: set Cancelled, return 200 with status Cancelled; 409 with error message when no longer Placed, status unchanged; 404 for another buyer's order, status unchanged; Stock unchanged on cancel | G24: Factory | H24: REQ-33, REQ-34, REQ-27, REQ-25 | I24: EST-9 | J24: 7.21 | K24: 12.61 | L24: 0.82 | M24: 2.76
C26: Development Total Efforts (in hours) | D26: =D9+D12+D16+D20 -> 30.57 | E26: =E9+E12+E16+E20 -> 51.55 | J26: =J9+J12+J16+J20 -> 62.58 | K26: =K9+K12+K16+K20 -> 110.56 | L26: =L9+L12+L16+L20 -> 7.18 | M26: =M9+M12+M16+M20 -> 24.14
B29: S.No | C29: Other Development Activities | D29: Human min (h) | E29: Human max (h) | F29: Comments | G29: Executor | H29: Requirement id(s) | I29: Task id | J29: Agent min (h) | K29: Agent max (h) | L29: API min ($) | M29: API max ($)
B30: 1 | C30: None | D30: 0 | E30: 0 | J30: 0 | K30: 0 | L30: 0 | M30: 0
C31: Post Development Activities Total Efforts (in hours) | D31: =SUM(D30:D30) -> 0 | E31: =SUM(E30:E30) -> 0 | J31: =SUM(J30:J30) -> 0 | K31: =SUM(K30:K30) -> 0 | L31: =SUM(L30:L30) -> 0 | M31: =SUM(M30:M30) -> 0
B34: S.No | C34: Research Task (if any) | D34: Human min (h) | E34: Human max (h) | F34: Comments | G34: Executor | H34: Requirement id(s) | I34: Task id | J34: Agent min (h) | K34: Agent max (h) | L34: API min ($) | M34: API max ($)
B35: 1 | C35: None | D35: 0 | E35: 0 | F35: No research task in this estimate | J35: 0 | K35: 0 | L35: 0 | M35: 0
C36: Research Total Efforts (in hours) | D36: =SUM(D35:D35) -> 0 | E36: =SUM(E35:E35) -> 0 | J36: =SUM(J35:J35) -> 0 | K36: =SUM(K35:K35) -> 0 | L36: =SUM(L35:L35) -> 0 | M36: =SUM(M35:M35) -> 0
B39: S.No | C39: Assumptions & Constraints
B40: 1 | C40: Does the 'Place order' button also need the cart to have at least one line, or is that already covered because checkout is hidden when the cart is empty? → assumed: Covered already: checkout is hidden when the cart is empty, and the API also refuses an order with no lines
B41: 2 | C41: Does placing (or cancelling) an order change the stock quantity in the existing parts database? → assumed: No: stock is read-only and orders never change it
B42: 3 | C42: What happens when a cart quantity is more than the current stock (or the part is now out of stock) at the moment the buyer presses 'Place order'? → assumed: The API checks stock again, rejects the order, lowers the affected lines to the stock now available with 'Only n available', and keeps the cart
B43: 4 | C43: Where is the cart kept? → assumed: In the browser's local storage for the signed-in buyer (kept across page reloads on the same device)
B44: 5 | C44: How does the API find out which buyer is making a request through the existing company login? → assumed: The API checks the existing company login's session token or cookie and reads the buyer ID from it
B45: 6 | C45: Nothing in this work moves an order to Packed, Dispatched or Delivered (no admin screens, no integrations). How do statuses change after Placed? → assumed: Staff update the status directly in the database, outside this work; the portal only shows it
B46: 7 | C46: Which unit price is saved on an order line, and what does the order 'total' include? → assumed: The part's current price when the order is placed; total = subtotal + delivery charge
B47: 8 | C47: How are 'ORD-' + 6-digit order numbers generated? → assumed: Sequential from a database sequence, zero-padded (ORD-000001)
B48: 9 | C48: Should the delivery prices (£0 / £9.99), the stock thresholds (5) and the page size (20) be fixed in the code or set in configuration? → assumed: Fixed constants in the code
B49: 10 | C49: What happens if the order's status changes from Placed (e.g. to Packed) after the buyer opened it but before they confirm cancelling? → assumed: The API cancels only if the status is still Placed; otherwise it refuses, shows a message and refreshes the order
B50: 11 | C50: What happens if placing an order fails (network or server error)? → assumed: Show an error message, keep the cart and checkout details, and let the buyer try again
B51: 12 | C51: What happens when a quantity is set to 0, left blank, set above 99, or isn't a whole number? → assumed: Set it to the nearest value in range (blank or 0 becomes 1, above 99 becomes 99)
... B67: 28 | C67: Split before the build: EST-1, EST-3, EST-6, EST-13 (agent work over 16 h or very large is split into smaller tasks; the hours stay as estimated).
B70: S.No | C70: Risks
...

Sheet Dev Mobile Estimates
B2: Development Estimates for Parts Quick Order
B3: 2026-10-05
B4: by mhamza
B5: Not in scope: no work in this estimate
C6: Grand Total (in hours) | D6: =D11+D16+D21 -> 0 | E6: =E11+E16+E21 -> 0 | F6: Sum of development, other activities and research efforts. | I6: Agent total (h) | J6: =J11+J16+J21 -> 0 | K6: =K11+K16+K21 -> 0
B8: S.No | C8: Task | D8: Human min (h) | E8: Human max (h) | F8: Comments | G8: Executor | H8: Requirement id(s) | I8: Task id | J8: Agent min (h) | K8: Agent max (h) | L8: API min ($) | M8: API max ($)
C9: None | D9: 0 | E9: 0 | J9: 0 | K9: 0 | L9: 0 | M9: 0
C11: Development Total Efforts (in hours) | D11: =D9 -> 0 | E11: =E9 -> 0 | J11: =J9 -> 0 | K11: =K9 -> 0 | L11: =L9 -> 0 | M11: =M9 -> 0
B14: S.No | C14: Other Development Activities | D14: Human min (h) | E14: Human max (h) | F14: Comments | G14: Executor | H14: Requirement id(s) | I14: Task id | J14: Agent min (h) | K14: Agent max (h) | L14: API min ($) | M14: API max ($)
B15: 1 | C15: None | D15: 0 | E15: 0 | J15: 0 | K15: 0 | L15: 0 | M15: 0
C16: Post Development Activities Total Efforts (in hours) | D16: =SUM(D15:D15) -> 0 | E16: =SUM(E15:E15) -> 0 | J16: =SUM(J15:J15) -> 0 | K16: =SUM(K15:K15) -> 0 | L16: =SUM(L15:L15) -> 0 | M16: =SUM(M15:M15) -> 0
B19: S.No | C19: Research Task (if any) | D19: Human min (h) | E19: Human max (h) | F19: Comments | G19: Executor | H19: Requirement id(s) | I19: Task id | J19: Agent min (h) | K19: Agent max (h) | L19: API min ($) | M19: API max ($)
B20: 1 | C20: None | D20: 0 | E20: 0 | F20: No research task in this estimate | J20: 0 | K20: 0 | L20: 0 | M20: 0
C21: Research Total Efforts (in hours) | D21: =SUM(D20:D20) -> 0 | E21: =SUM(E20:E20) -> 0 | J21: =SUM(J20:J20) -> 0 | K21: =SUM(K20:K20) -> 0 | L21: =SUM(L20:L20) -> 0 | M21: =SUM(M20:M20) -> 0

Sheet Dev Web Estimates
B2: Development Estimates for Parts Quick Order
B3: 2026-10-05
B4: by mhamza
C6: Grand Total (in hours) | D6: =D25+D30+D35 -> 6.55 | E6: =E25+E30+E35 -> 13.1 | F6: Sum of development, other activities and research efforts. | I6: Agent total (h) | J6: =J25+J30+J35 -> 65.37 | K6: =K25+K30+K35 -> 109.28
B8: S.No | C8: Task | D8: Human min (h) | E8: Human max (h) | F8: Comments | G8: Executor | H8: Requirement id(s) | I8: Task id | J8: Agent min (h) | K8: Agent max (h) | L8: API min ($) | M8: API max ($)
B9: 1 | C9: Portal shell, navigation and cross-cutting | D9: =SUM(D10:D11) -> 6.55 | E9: =SUM(E10:E11) -> 13.1 | J9: =SUM(J10:J11) -> 12.31 | K9: =SUM(K10:K11) -> 23.18 | L9: =SUM(L10:L11) -> 1.47 | M9: =SUM(M10:M11) -> 4.95
C10: Portal app shell (web) | D10: 0 | E10: 0 | F10: Routes /parts, /cart, /orders; Header with links to the other two screens and live cart count; Company login session wiring and buyer ID; Error page; Responsive layout without horizontal scroll from 360 px; Visible focus and keyboard navigation; Prices formatted as £ with 2 decimals, English only (NFR-6) | G10: Factory | H10: REQ-1, REQ-9, REQ-36, REQ-37 | I10: EST-10 | J10: 5.76 | K10: 10.08 | L10: 0.66 | M10: 2.21
C11: Production release of API and portal | D11: 6.55 | E11: 13.1 | F11: Production launch delivers no requirement on its own | G11: Joint | I11: EST-22 | J11: 6.55 | K11: 13.1 | L11: 0.81 | M11: 2.74
B13: 2 | C13: Find parts | D13: =SUM(D14:D14) -> 0 | E13: =SUM(E14:E14) -> 0 | J13: =SUM(J14:J14) -> 6 | K13: =SUM(K14:K14) -> 10 | L13: =SUM(L14:L14) -> 0.66 | M13: =SUM(M14:M14) -> 2.23
C14: Find parts screen (web) | D14: 0 | E14: 0 | F14: Search box with "Type at least 2 characters" hint; Category and brand filters with All; Result rows: image, name, part number, brand, price, stock badge with text; Previous/Next paging, back to page 1 on search or filter change; Add to cart, disabled when out of stock; header count bumps with success message; Go to cart (n) link; States: loading skeleton, empty "No parts match" with Clear search and filters, error with Try again, out of stock, low stock, added; First page displayed within 2 seconds with 5,000 parts | G14: Factory | H14: REQ-1, REQ-2, REQ-3, REQ-4, REQ-5, REQ-6, REQ-7, REQ-8, REQ-9, REQ-10, REQ-36, REQ-37, REQ-38 | I14: EST-12 | J14: 6 | K14: 10 | L14: 0.66 | M14: 2.23
B16: 3 | C16: Cart and checkout | D16: =SUM(D17:D19) -> 0 | E16: =SUM(E17:E19) -> 0 | J16: =SUM(J17:J19) -> 31.66 | K16: =SUM(K17:K19) -> 50.9 | L16: =SUM(L17:L19) -> 3.43 | M16: =SUM(M17:M19) -> 11.51
C17: CartStore in browser local storage per buyer | D17: 0 | E17: 0 | F17: addPart: add line quantity 1 or +1; out-of-stock part not added; capped at stock with "Only n available"; count(): total of all quantities; lines(): name, partNumber, unitPrice, quantity, lineTotal; setQuantity: blank/0 → 1, above 99 → 99, non-whole → nearest; above stock → stock with "Only n available"; removeLine; subtotal() and totals(STANDARD £0.00 / NEXT_DAY £9.99); Persist lines in local storage under buyer ID; refresh(partsClient): current prices only, remove 0-stock lines with "<part name> is now out of stock", on failure error field and null prices/totals; applyStockLimits from 409: lower lines with "Only n available", remove 0-stock lines with message, keep others | G17: Factory | H17: REQ-8, REQ-9, REQ-10, REQ-11, REQ-12, REQ-13, REQ-14, REQ-15, REQ-16, REQ-19, REQ-39, REQ-41, REQ-42, REQ-43 | I17: EST-11 | J17: 7.02 | K17: 11.7 | L17: 0.78 | M17: 2.61
C18: Cart lines with live prices (web) | D18: 0 | E18: 0 | F18: Lines table: part, part no., unit price, editable qty, line total, Remove; Instant recalculation of line and order totals; Quantity correction with "Only n available"; Inline alert "<part name> is now out of stock" when a line is removed; Loading state while current prices are fetched; Price error state: lines without prices, error message, Try again, checkout hidden; Empty state "Your cart is empty" with link to Find parts, checkout hidden | G18: Factory | H18: REQ-9, REQ-11, REQ-12, REQ-13, REQ-14, REQ-15, REQ-17, REQ-41, REQ-42, REQ-43, REQ-36, REQ-37 | I18: EST-13 | J18: 19.6 | K18: 30.8 | L18: 2.09 | M18: 7.03
C19: Checkout form and place order (web) | D19: 0 | E19: 0 | F19: Delivery address textarea 5–200 characters, empty each time, with labelled error; Delivery option radio Standard £0.00 / Next day £9.99; Order summary: items, subtotal, delivery charge, total; Place order enabled only when valid; disabled while submitting (one request); Success: show order number, empty cart, link to My orders; Network error toast: check My orders before retrying; server error toast: cart and details kept; 409 conflict: apply stock limits to lines with messages | G19: Factory | H19: REQ-18, REQ-19, REQ-20, REQ-21, REQ-22, REQ-23, REQ-24, REQ-39, REQ-40, REQ-36, REQ-37 | I19: EST-14 | J19: 5.04 | K19: 8.4 | L19: 0.56 | M19: 1.87
B21: 4 | C21: My orders | D21: =SUM(D22:D23) -> 0 | E21: =SUM(E22:E23) -> 0 | J21: =SUM(J22:J23) -> 15.4 | K21: =SUM(K22:K23) -> 25.2 | L21: =SUM(L22:L23) -> 1.68 | M21: =SUM(M22:M23) -> 5.66
C22: My orders list (web) | D22: 0 | E22: 0 | F22: Table: order, date placed, items, total, status (text label), newest first; Status filter chips: All statuses, Placed, Packed, Dispatched, Delivered, Cancelled; View order opens panel on the same page; States: loading skeleton, empty "No orders yet" with link to Find parts, filtered empty, error with Try again | G22: Factory | H22: REQ-1, REQ-28, REQ-29, REQ-35, REQ-36, REQ-37 | I22: EST-15 | J22: 8.4 | K22: 14 | L22: 0.93 | M22: 3.12
C23: Order detail drawer, timeline and cancel (web) | D23: 0 | E23: 0 | F23: Drawer overlay: lines, address, delivery option, total, status; Timeline Placed → Packed → Dispatched → Delivered with current status marked by text; Cancel order button only while Placed; Confirm dialog (Yes, cancel order / Keep order); Success toast and status Cancelled; 409 toast: can no longer be cancelled, panel refreshes | G23: Factory | H23: REQ-1, REQ-30, REQ-31, REQ-32, REQ-33, REQ-34, REQ-37 | I23: EST-16 | J23: 7 | K23: 11.2 | L23: 0.75 | M23: 2.54
C25: Development Total Efforts (in hours) | D25: =D9+D13+D16+D21 -> 6.55 | E25: =E9+E13+E16+E21 -> 13.1 | J25: =J9+J13+J16+J21 -> 65.37 | K25: =K9+K13+K16+K21 -> 109.28 | L25: =L9+L13+L16+L21 -> 7.24 | M25: =M9+M13+M16+M21 -> 24.35
B28: S.No | C28: Other Development Activities | D28: Human min (h) | E28: Human max (h) | F28: Comments | G28: Executor | H28: Requirement id(s) | I28: Task id | J28: Agent min (h) | K28: Agent max (h) | L28: API min ($) | M28: API max ($)
B29: 1 | C29: None | D29: 0 | E29: 0 | J29: 0 | K29: 0 | L29: 0 | M29: 0
C30: Post Development Activities Total Efforts (in hours) | D30: =SUM(D29:D29) -> 0 | E30: =SUM(E29:E29) -> 0 | J30: =SUM(J29:J29) -> 0 | K30: =SUM(K29:K29) -> 0 | L30: =SUM(L29:L29) -> 0 | M30: =SUM(M29:M29) -> 0
B33: S.No | C33: Research Task (if any) | D33: Human min (h) | E33: Human max (h) | F33: Comments | G33: Executor | H33: Requirement id(s) | I33: Task id | J33: Agent min (h) | K33: Agent max (h) | L33: API min ($) | M33: API max ($)
B34: 1 | C34: None | D34: 0 | E34: 0 | F34: No research task in this estimate | J34: 0 | K34: 0 | L34: 0 | M34: 0
C35: Research Total Efforts (in hours) | D35: =SUM(D34:D34) -> 0 | E35: =SUM(E34:E34) -> 0 | J35: =SUM(J34:J34) -> 0 | K35: =SUM(K34:K34) -> 0 | L35: =SUM(L34:L34) -> 0 | M35: =SUM(M34:M34) -> 0
B38: S.No | C38: Assumptions & Constraints
B39: 1 | C39: Does the 'Place order' button also need the cart to have at least one line, or is that already covered because checkout is hidden when the cart is empty? → assumed: Covered already: checkout is hidden when the cart is empty, and the API also refuses an order with no lines
B40: 2 | C40: Does placing (or cancelling) an order change the stock quantity in the existing parts database? → assumed: No: stock is read-only and orders never change it
B41: 3 | C41: What happens when a cart quantity is more than the current stock (or the part is now out of stock) at the moment the buyer presses 'Place order'? → assumed: The API checks stock again, rejects the order, lowers the affected lines to the stock now available with 'Only n available', and keeps the cart
B42: 4 | C42: Where is the cart kept? → assumed: In the browser's local storage for the signed-in buyer (kept across page reloads on the same device)
B43: 5 | C43: How does the API find out which buyer is making a request through the existing company login? → assumed: The API checks the existing company login's session token or cookie and reads the buyer ID from it
B44: 6 | C44: Nothing in this work moves an order to Packed, Dispatched or Delivered (no admin screens, no integrations). How do statuses change after Placed? → assumed: Staff update the status directly in the database, outside this work; the portal only shows it
B45: 7 | C45: Which unit price is saved on an order line, and what does the order 'total' include? → assumed: The part's current price when the order is placed; total = subtotal + delivery charge
B46: 8 | C46: How are 'ORD-' + 6-digit order numbers generated? → assumed: Sequential from a database sequence, zero-padded (ORD-000001)
B47: 9 | C47: Should the delivery prices (£0 / £9.99), the stock thresholds (5) and the page size (20) be fixed in the code or set in configuration? → assumed: Fixed constants in the code
B48: 10 | C48: What happens if the order's status changes from Placed (e.g. to Packed) after the buyer opened it but before they confirm cancelling? → assumed: The API cancels only if the status is still Placed; otherwise it refuses, shows a message and refreshes the order
B49: 11 | C49: What happens if placing an order fails (network or server error)? → assumed: Show an error message, keep the cart and checkout details, and let the buyer try again
B50: 12 | C50: What happens when a quantity is set to 0, left blank, set above 99, or isn't a whole number? → assumed: Set it to the nearest value in range (blank or 0 becomes 1, above 99 becomes 99)
... B66: 28 | C66: Split before the build: EST-1, EST-3, EST-6, EST-13 (agent work over 16 h or very large is split into smaller tasks; the hours stay as estimated).
B69: S.No | C69: Risks
B70: 1 | C70: Estimates will increase in case of change in requirement

Sheet QA Estimates
B2: QA Estimates for Parts Quick Order
B3: 2026-10-05
B4: by mhamza
C6: Grand Total Efforts (in hours) | D6: =D23 -> 4 | E6: =E23 -> 8 | F6: Sum of QA and Misc. | I6: Agent total (h) | J6: =J23 -> 18.9 | K6: =K23 -> 35.8
B8: S.No | C8: Estimation Summary | D8: Human min (h) | E8: Human max (h) | F8: Comments | G8: Executor | H8: Requirement id(s) | I8: Task id | J8: Agent min (h) | K8: Agent max (h) | L8: API min ($) | M8: API max ($)
B9: 1 | C9: Test Plan/Strategy | D9: 0 | E9: 0 | F9: Test planning, with the test plan, strategy and traceability matrix as outputs. Not sized in this estimate | J9: 0 | K9: 0 | L9: 0 | M9: 0
B10: 2 | C10: Set up of Test Environments | D10: 0 | E10: 0 | F10: Setting up code and white box test environments. Not sized in this estimate | J10: 0 | K10: 0 | L10: 0 | M10: 0
B11: 3 | C11: Validation and Smoke test cases | D11: =SUM(D12:D14) -> 0 | E11: =SUM(E12:E14) -> 0 | F11: Test cases to execute while debugging and white box testing | J11: =SUM(J12:J14) -> 9 | K11: =SUM(K12:K14) -> 18 | L11: =SUM(L12:L14) -> 1.11 | M11: =SUM(M12:M14) -> 3.77
C12: Test cases: Find parts and parts API, including load test | D12: 0 | E12: 0 | F12: API cases AC-2.x to AC-7.x; Load test AC-38.1 (p95 < 500 ms) and AC-38.2 (2 s first page); Manual cases for paging reset, clear button, disabled Add to cart | G12: Factory | H12: REQ-2, REQ-3, REQ-4, REQ-5, REQ-6, REQ-7, REQ-8, REQ-10, REQ-38 | I12: EST-17 | J12: 3 | K12: 6 | L12: 0.37 | M12: 1.26
C13: Test cases: Cart, checkout and place order | D13: 0 | E13: 0 | F13: CartStore and CheckoutForm unit cases; Orders API cases for 201, 400, 409, stock unchanged; Manual cases for error, conflict, price failure and success states | G13: Factory | H13: REQ-11, REQ-12, REQ-13, REQ-14, REQ-15, REQ-16, REQ-17, REQ-18, REQ-19, REQ-20, REQ-21, REQ-22, REQ-23, REQ-24, REQ-25, REQ-39, REQ-40, REQ-41, REQ-42, REQ-43 | I13: EST-18 | J13: 3 | K13: 6 | L13: 0.37 | M13: 1.26
C14: Test cases: My orders and cancel | D14: 0 | E14: 0 | F14: Ownership 404 cases; List order, filter, detail cases; Cancel success and 409 cases, confirmation decline | G14: Factory | H14: REQ-27, REQ-28, REQ-29, REQ-30, REQ-31, REQ-32, REQ-33, REQ-34, REQ-35 | I14: EST-19 | J14: 3 | K14: 6 | L14: 0.37 | M14: 1.25
B15: 4 | C15: Validation testing | D15: =SUM(D16:D16) -> 0 | E15: =SUM(E16:E16) -> 0 | F15: Testing cycles; the detail is below | J15: =SUM(J16:J16) -> 6 | K15: =SUM(K16:K16) -> 10 | L15: =SUM(L16:L16) -> 0.66 | M15: =SUM(M16:M16) -> 2.23
C16: Testing Cycle 1 | D16: =D29 -> 0 | E16: =E29 -> 0 | J16: =J29 -> 6 | K16: =K29 -> 10 | L16: =L29 -> 0.66 | M16: =M29 -> 2.23
B17: 5 | C17: Smoke testing | D17: 0 | E17: 0 | F17: Smoke testing after each deployment, including preparation. Not sized in this estimate | J17: 0 | K17: 0 | L17: 0 | M17: 0
B18: 6 | C18: Multi Browser Compatibility testing | D18: =SUM(D19:D19) -> 0 | E18: =SUM(E19:E19) -> 0 | F18: Browser, OS and device compatibility | J18: =SUM(J19:J19) -> 3.9 | K18: =SUM(K19:K19) -> 7.8 | L18: =SUM(L19:L19) -> 0.48 | M18: =SUM(M19:M19) -> 1.63
C19: Test cases: accessibility, responsive and browsers | D19: 0 | E19: 0 | F19: Automated axe scan per screen, 0 serious or critical (NFR-3); Keyboard-only journey with screen reader labels; 360/768/1280 px widths on latest 2 Chrome, Edge, Safari, Firefox | G19: Factory | H19: REQ-1, REQ-36, REQ-37 | I19: EST-20 | J19: 3.9 | K19: 7.8 | L19: 0.48 | M19: 1.63
B20: 7 | C20: UAT | D20: =SUM(D21:D21) -> 4 | E20: =SUM(E21:E21) -> 8 | F20: Client user acceptance testing support | J20: =SUM(J21:J21) -> 0 | K20: =SUM(K21:K21) -> 0 | L20: =SUM(L21:L21) -> 0 | M20: =SUM(M21:M21) -> 0
C21: Client acceptance testing | D21: 4 | E21: 8 | F21: Client UAT delivers no requirement on its own | G21: Human | I21: EST-24 | J21: 0 | K21: 0 | L21: 0 | M21: 0
B22: 8 | C22: Misc. Optional testing | D22: 0 | E22: 0 | F22: Other testing named in the breakdown, and supervisor gate time. Not sized in this estimate | J22: 0 | K22: 0 | L22: 0 | M22: 0
C23: Total QA Efforts | D23: =D9+D10+D11+D15+D17+D18+D20+D22 -> 4 | E23: =E9+E10+E11+E15+E17+E18+E20+E22 -> 8 | F23: Total hours of QA | J23: =J9+J10+J11+J15+J17+J18+J20+J22 -> 18.9 | K23: =K9+K10+K11+K15+K17+K18+K20+K22 -> 35.8 | L23: =L9+L10+L11+L15+L17+L18+L20+L22 -> 2.25 | M23: =M9+M10+M11+M15+M17+M18+M20+M22 -> 7.63
B26: S.No | C26: Validation Testing | D26: Human min (h) | E26: Human max (h) | F26: Comments | G26: Executor | H26: Requirement id(s) | I26: Task id | J26: Agent min (h) | K26: Agent max (h) | L26: API min ($) | M26: API max ($)
C27: Testing Cycle 1
B28: 1 | C28: End-to-end test: find, add, check out, view and cancel | D28: 0 | E28: 0 | F28: Search, add to cart, header count, place order, order number, open in My orders, cancel | G28: Factory | H28: REQ-1, REQ-4, REQ-8, REQ-9, REQ-18, REQ-20, REQ-23, REQ-28, REQ-30, REQ-32, REQ-33 | I28: EST-21 | J28: 6 | K28: 10 | L28: 0.66 | M28: 2.23
C29: Total Testing Cycle 1 | D29: =D28 -> 0 | E29: =E28 -> 0 | F29: Sum of testing cycle 1 | J29: =J28 -> 6 | K29: =K28 -> 10 | L29: =L28 -> 0.66 | M29: =M28 -> 2.23
B32: S.No | C32: Assumptions & Constraints
B33: 1 | C33: Does the 'Place order' button also need the cart to have at least one line, or is that already covered because checkout is hidden when the cart is empty? → assumed: Covered already: checkout is hidden when the cart is empty, and the API also refuses an order with no lines
B34: 2 | C34: Does placing (or cancelling) an order change the stock quantity in the existing parts database? → assumed: No: stock is read-only and orders never change it
B35: 3 | C35: What happens when a cart quantity is more than the current stock (or the part is now out of stock) at the moment the buyer presses 'Place order'? → assumed: The API checks stock again, rejects the order, lowers the affected lines to the stock now available with 'Only n available', and keeps the cart
B36: 4 | C36: Where is the cart kept? → assumed: In the browser's local storage for the signed-in buyer (kept across page reloads on the same device)
B37: 5 | C37: How does the API find out which buyer is making a request through the existing company login? → assumed: The API checks the existing company login's session token or cookie and reads the buyer ID from it
B38: 6 | C38: Nothing in this work moves an order to Packed, Dispatched or Delivered (no admin screens, no integrations). How do statuses change after Placed? → assumed: Staff update the status directly in the database, outside this work; the portal only shows it
B39: 7 | C39: Which unit price is saved on an order line, and what does the order 'total' include? → assumed: The part's current price when the order is placed; total = subtotal + delivery charge
B40: 8 | C40: How are 'ORD-' + 6-digit order numbers generated? → assumed: Sequential from a database sequence, zero-padded (ORD-000001)
B41: 9 | C41: Should the delivery prices (£0 / £9.99), the stock thresholds (5) and the page size (20) be fixed in the code or set in configuration? → assumed: Fixed constants in the code
B42: 10 | C42: What happens if the order's status changes from Placed (e.g. to Packed) after the buyer opened it but before they confirm cancelling? → assumed: The API cancels only if the status is still Placed; otherwise it refuses, shows a message and refreshes the order
B43: 11 | C43: What happens if placing an order fails (network or server error)? → assumed: Show an error message, keep the cart and checkout details, and let the buyer try again
B44: 12 | C44: What happens when a quantity is set to 0, left blank, set above 99, or isn't a whole number? → assumed: Set it to the nearest value in range (blank or 0 becomes 1, above 99 becomes 99)
... B60: 28 | C60: Split before the build: EST-1, EST-3, EST-6, EST-13 (agent work over 16 h or very large is split into smaller tasks; the hours stay as estimated).
B63: S.No | C63: Risks
B64: 1 | C64: Estimates will increase in case of change in requirement

Sheet Design Estimates
B2: Design Estimates for Parts Quick Order
B3: 2026-10-05
B4: by mhamza
C6: Grand Total (in hours) | D6: =D12+D17+D22 -> 2 | E6: =E12+E17+E22 -> 4 | F6: Sum of development, other activities and research efforts. | I6: Agent total (h) | J6: =J12+J17+J22 -> 0 | K6: =K12+K17+K22 -> 0
B8: S.No | C8: Task | D8: Human min (h) | E8: Human max (h) | F8: Comments | G8: Executor | H8: Requirement id(s) | I8: Task id | J8: Agent min (h) | K8: Agent max (h) | L8: API min ($) | M8: API max ($)
B9: 1 | C9: Portal shell, navigation and cross-cutting | D9: =SUM(D10:D10) -> 2 | E9: =SUM(E10:E10) -> 4 | J9: =SUM(J10:J10) -> 0 | K9: =SUM(K10:K10) -> 0 | L9: =SUM(L10:L10) -> 0 | M9: =SUM(M10:M10) -> 0
C10: Client design review and approval | D10: 2 | E10: 4 | F10: Client walkthrough and sign-off of the approved design | G10: Human | I10: EST-23 | J10: 0 | K10: 0 | L10: 0 | M10: 0
C12: Development Total Efforts (in hours) | D12: =D9 -> 2 | E12: =E9 -> 4 | J12: =J9 -> 0 | K12: =K9 -> 0 | L12: =L9 -> 0 | M12: =M9 -> 0
B15: S.No | C15: Other Development Activities | D15: Human min (h) | E15: Human max (h) | F15: Comments | G15: Executor | H15: Requirement id(s) | I15: Task id | J15: Agent min (h) | K15: Agent max (h) | L15: API min ($) | M15: API max ($)
B16: 1 | C16: None | D16: 0 | E16: 0 | J16: 0 | K16: 0 | L16: 0 | M16: 0
C17: Post Development Activities Total Efforts (in hours) | D17: =SUM(D16:D16) -> 0 | E17: =SUM(E16:E16) -> 0 | J17: =SUM(J16:J16) -> 0 | K17: =SUM(K16:K16) -> 0 | L17: =SUM(L16:L16) -> 0 | M17: =SUM(M16:M16) -> 0
B20: S.No | C20: Research Task (if any) | D20: Human min (h) | E20: Human max (h) | F20: Comments | G20: Executor | H20: Requirement id(s) | I20: Task id | J20: Agent min (h) | K20: Agent max (h) | L20: API min ($) | M20: API max ($)
B21: 1 | C21: None | D21: 0 | E21: 0 | F21: No research task in this estimate | J21: 0 | K21: 0 | L21: 0 | M21: 0
C22: Research Total Efforts (in hours) | D22: =SUM(D21:D21) -> 0 | E22: =SUM(E21:E21) -> 0 | J22: =SUM(J21:J21) -> 0 | K22: =SUM(K21:K21) -> 0 | L22: =SUM(L21:L21) -> 0 | M22: =SUM(M21:M21) -> 0
B25: S.No | C25: Assumptions & Constraints
B26: 1 | C26: Does the 'Place order' button also need the cart to have at least one line, or is that already covered because checkout is hidden when the cart is empty? → assumed: Covered already: checkout is hidden when the cart is empty, and the API also refuses an order with no lines
B27: 2 | C27: Does placing (or cancelling) an order change the stock quantity in the existing parts database? → assumed: No: stock is read-only and orders never change it
B28: 3 | C28: What happens when a cart quantity is more than the current stock (or the part is now out of stock) at the moment the buyer presses 'Place order'? → assumed: The API checks stock again, rejects the order, lowers the affected lines to the stock now available with 'Only n available', and keeps the cart
B29: 4 | C29: Where is the cart kept? → assumed: In the browser's local storage for the signed-in buyer (kept across page reloads on the same device)
B30: 5 | C30: How does the API find out which buyer is making a request through the existing company login? → assumed: The API checks the existing company login's session token or cookie and reads the buyer ID from it
B31: 6 | C31: Nothing in this work moves an order to Packed, Dispatched or Delivered (no admin screens, no integrations). How do statuses change after Placed? → assumed: Staff update the status directly in the database, outside this work; the portal only shows it
B32: 7 | C32: Which unit price is saved on an order line, and what does the order 'total' include? → assumed: The part's current price when the order is placed; total = subtotal + delivery charge
B33: 8 | C33: How are 'ORD-' + 6-digit order numbers generated? → assumed: Sequential from a database sequence, zero-padded (ORD-000001)
B34: 9 | C34: Should the delivery prices (£0 / £9.99), the stock thresholds (5) and the page size (20) be fixed in the code or set in configuration? → assumed: Fixed constants in the code
B35: 10 | C35: What happens if the order's status changes from Placed (e.g. to Packed) after the buyer opened it but before they confirm cancelling? → assumed: The API cancels only if the status is still Placed; otherwise it refuses, shows a message and refreshes the order
B36: 11 | C36: What happens if placing an order fails (network or server error)? → assumed: Show an error message, keep the cart and checkout details, and let the buyer try again
B37: 12 | C37: What happens when a quantity is set to 0, left blank, set above 99, or isn't a whole number? → assumed: Set it to the nearest value in range (blank or 0 becomes 1, above 99 becomes 99)
... B53: 28 | C53: Split before the build: EST-1, EST-3, EST-6, EST-13 (agent work over 16 h or very large is split into smaller tasks; the hours stay as estimated).
B56: S.No | C56: Risks
B57: 1 | C57: Estimates will increase in case of change in requirement

Sheet Other Estimates
B2: Other Estimates for Parts Quick Order
B3: 2026-10-05
B4: by mhamza
B6: GD
B7: Not in scope: no work in this estimate
B8: S.No | C8: Task | D8: Human min (h) | E8: Human max (h) | F8: Comments | G8: Executor | H8: Requirement id(s) | I8: Task id | J8: Agent min (h) | K8: Agent max (h) | L8: API min ($) | M8: API max ($)
B9: 1 | C9: None | D9: 0 | E9: 0 | J9: 0 | K9: 0 | L9: 0 | M9: 0
C10: GD TOTAL | D10: =SUM(D9:D9) -> 0 | E10: =SUM(E9:E9) -> 0 | J10: =SUM(J9:J9) -> 0 | K10: =SUM(K9:K9) -> 0 | L10: =SUM(L9:L9) -> 0 | M10: =SUM(M9:M9) -> 0
B13: PM
B14: S.No | C14: Task | D14: Human min (h) | E14: Human max (h) | F14: Comments | G14: Executor | H14: Requirement id(s) | I14: Task id | J14: Agent min (h) | K14: Agent max (h) | L14: API min ($) | M14: API max ($)
B15: 1 | C15: Project management: client liaison | D15: 4 | E15: 8 | F15: Client calls, scope decisions and sign-offs | G15: Human | I15: EST-25 | J15: 0 | K15: 0 | L15: 0 | M15: 0
C16: PM TOTAL | D16: =SUM(D15:D15) -> 4 | E16: =SUM(E15:E15) -> 8 | J16: =SUM(J15:J15) -> 0 | K16: =SUM(K15:K15) -> 0 | L16: =SUM(L15:L15) -> 0 | M16: =SUM(M15:M15) -> 0
B19: PDM
B20: S.No | C20: Task | D20: Human min (h) | E20: Human max (h) | F20: Comments | G20: Executor | H20: Requirement id(s) | I20: Task id | J20: Agent min (h) | K20: Agent max (h) | L20: API min ($) | M20: API max ($)
B21: 1 | C21: Handover notes | D21: 0 | E21: 0 | F21: Documentation delivers no requirement on its own | G21: Factory | I21: EST-26 | J21: 2.88 | K21: 5.76 | L21: 0.36 | M21: 1.2
C22: PDM TOTAL | D22: =SUM(D21:D21) -> 0 | E22: =SUM(E21:E21) -> 0 | J22: =SUM(J21:J21) -> 2.88 | K22: =SUM(K21:K21) -> 5.76 | L22: =SUM(L21:L21) -> 0.36 | M22: =SUM(M21:M21) -> 1.2
B25: Cross-cutting
B26: S.No | C26: Task | D26: Human min (h) | E26: Human max (h) | F26: Comments | G26: Executor | H26: Requirement id(s) | I26: Task id | J26: Agent min (h) | K26: Agent max (h) | L26: API min ($) | M26: API max ($)
B27: 1 | C27: None | D27: 0 | E27: 0 | J27: 0 | K27: 0 | L27: 0 | M27: 0
C28: Cross-cutting TOTAL | D28: =SUM(D27:D27) -> 0 | E28: =SUM(E27:E27) -> 0 | J28: =SUM(J27:J27) -> 0 | K28: =SUM(K27:K27) -> 0 | L28: =SUM(L27:L27) -> 0 | M28: =SUM(M27:M27) -> 0

Sheet All Tasks
B1: All tasks: Parts Quick Order
B2: Filter or sort any column. The Total row adds up only the rows the filter shows.
B4: Task id | C4: Task | D4: Track | E4: Module | F4: Executor | G4: Requirement id(s) | H4: Human min (h) | I4: Human max (h) | J4: Agent min (h) | K4: Agent max (h) | L4: API min ($) | M4: API max ($)
B5: EST-1 | C5: Environments, CI/CD and hosting for API and portal | D5: Backend | E5: Portal shell, navigation and cross-cutting | F5: Joint | H5: 17.47 | I5: 30.58 | J5: 17.47 | K5: 30.58 | L5: 1.99 | M5: 6.7
B6: EST-2 | C6: Orders data model, migrations and seed data | D6: Backend | E6: Placing orders (orders API) | F6: Factory | G6: REQ-20, REQ-28, REQ-30, REQ-38 | H6: 0 | I6: 0 | J6: 2.16 | K6: 4.32 | L6: 0.27 | M6: 0.9
B7: EST-3 | C7: Buyer identity from existing company login session | D7: Backend | E7: My orders | F7: Joint | G7: REQ-27, REQ-16 | H7: 13.1 | I7: 20.97 | J7: 13.1 | K7: 20.97 | L7: 1.41 | M7: 4.75
B8: EST-4 | C8: GET /api/parts: search, filters, paging, stock state | D8: Backend | E8: Find parts | F8: Factory | G8: REQ-2, REQ-3, REQ-4, REQ-5, REQ-38 | H8: 0 | I8: 0 | J8: 3.9 | K8: 7.8 | L8: 0.49 | M8: 1.63
B9: EST-5 | C9: GET /api/parts/brands | D9: Backend | E9: Find parts | F9: Factory | G9: REQ-5 | H9: 0 | I9: 0 | J9: 1.62 | K9: 3.24 | L9: 0.2 | M9: 0.68
B10: EST-6 | C10: POST /api/orders: place order rules | D10: Backend | E10: Placing orders (orders API) | F10: Factory | G10: REQ-20, REQ-21, REQ-22, REQ-25 | H10: 0 | I10: 0 | J10: 12.8 | K10: 22.4 | L10: 1.46 | M10: 4.91
B11: EST-7 | C11: GET /api/orders: buyer's orders list with status filter | D11: Backend | E11: My orders | F11: Factory | G11: REQ-27, REQ-28, REQ-29, REQ-35 | H11: 0 | I11: 0 | J11: 2.7 | K11: 5.4 | L11: 0.34 | M11: 1.13
B12: EST-8 | C12: GET /api/orders/{orderNumber}: order detail | D12: Backend | E12: My orders | F12: Factory | G12: REQ-27, REQ-30 | H12: 0 | I12: 0 | J12: 1.62 | K12: 3.24 | L12: 0.2 | M12: 0.68
B13: EST-9 | C13: POST /api/orders/{orderNumber}/cancel: cancel rules | D13: Backend | E13: My orders | F13: Factory | G13: REQ-33, REQ-34, REQ-27, REQ-25 | H13: 0 | I13: 0 | J13: 7.21 | K13: 12.61 | L13: 0.82 | M13: 2.76
B14: EST-10 | C14: Portal app shell (web) | D14: Web | E14: Portal shell, navigation and cross-cutting | F14: Factory | G14: REQ-1, REQ-9, REQ-36, REQ-37 | H14: 0 | I14: 0 | J14: 5.76 | K14: 10.08 | L14: 0.66 | M14: 2.21
B15: EST-11 | C15: CartStore in browser local storage per buyer | D15: Web | E15: Cart and checkout | F15: Factory | G15: REQ-8, REQ-9, REQ-10, REQ-11, REQ-12, REQ-13, REQ-14, REQ-15, REQ-16, REQ-19, REQ-39, REQ-41, REQ-42, REQ-43 | H15: 0 | I15: 0 | J15: 7.02 | K15: 11.7 | L15: 0.78 | M15: 2.61
B16: EST-12 | C16: Find parts screen (web) | D16: Web | E16: Find parts | F16: Factory | G16: REQ-1, REQ-2, REQ-3, REQ-4, REQ-5, REQ-6, REQ-7, REQ-8, REQ-9, REQ-10, REQ-36, REQ-37, REQ-38 | H16: 0 | I16: 0 | J16: 6 | K16: 10 | L16: 0.66 | M16: 2.23
B17: EST-13 | C17: Cart lines with live prices (web) | D17: Web | E17: Cart and checkout | F17: Factory | G17: REQ-9, REQ-11, REQ-12, REQ-13, REQ-14, REQ-15, REQ-17, REQ-41, REQ-42, REQ-43, REQ-36, REQ-37 | H17: 0 | I17: 0 | J17: 19.6 | K17: 30.8 | L17: 2.09 | M17: 7.03
... B25: EST-21 | C25: End-to-end test: find, add, check out, view and cancel | D25: QA | E25: Cart and checkout | F25: Factory | G25: REQ-1, REQ-4, REQ-8, REQ-9, REQ-18, REQ-20, REQ-23, REQ-28, REQ-30, REQ-32, REQ-33 | H25: 0 | I25: 0 | J25: 6 | K25: 10 | L25: 0.66 | M25: 2.23
B26: EST-22 | C26: Production release of API and portal | D26: Web | E26: Portal shell, navigation and cross-cutting | F26: Joint | H26: 6.55 | I26: 13.1 | J26: 6.55 | K26: 13.1 | L26: 0.81 | M26: 2.74
B27: EST-23 | C27: Client design review and approval | D27: Design | E27: Portal shell, navigation and cross-cutting | F27: Human | H27: 2 | I27: 4 | J27: 0 | K27: 0 | L27: 0 | M27: 0
B28: EST-24 | C28: Client acceptance testing | D28: QA | E28: Portal shell, navigation and cross-cutting | F28: Human | H28: 4 | I28: 8 | J28: 0 | K28: 0 | L28: 0 | M28: 0
B29: EST-25 | C29: Project management: client liaison | D29: PM | E29: Portal shell, navigation and cross-cutting | F29: Human | H29: 4 | I29: 8 | J29: 0 | K29: 0 | L29: 0 | M29: 0
B30: EST-26 | C30: Handover notes | D30: PDM | E30: Portal shell, navigation and cross-cutting | F30: Factory | H30: 0 | I30: 0 | J30: 2.88 | K30: 5.76 | L30: 0.36 | M30: 1.2
C31: Total (rows shown) | H31: =SUBTOTAL(9,H5:H30) -> 47.12 | I31: =SUBTOTAL(9,I5:I30) -> 84.65 | J31: =SUBTOTAL(9,J5:J30) -> 149.73 | K31: =SUBTOTAL(9,K5:K30) -> 261.4 | L31: =SUBTOTAL(9,L5:L30) -> 17.03 | M31: =SUBTOTAL(9,M5:M30) -> 57.32
